Workbook
Name UPDATE: 'Data Sheet'!$E$1

Sheet HistoricalFS
B2: ="Historical Financials Statements - "&'Data Sheet'!B1 -> Historical Financials Statements - ASIAN PAINTS LTD
B3: Years | C3: ='[1]Data Sheet'!B16 -> 42460 | D3: ='[1]Data Sheet'!C16 -> 42825 | E3: ='[1]Data Sheet'!D16 -> 43190 | F3: ='[1]Data Sheet'!E16 -> 43555 | G3: ='[1]Data Sheet'!F16 -> 43921 | H3: ='[1]Data Sheet'!G16 -> 44286 | I3: ='[1]Data Sheet'!H16 -> 44651 | J3: ='[1]Data Sheet'!I16 -> 45016 | ... L3: ='[1]Data Sheet'!K16 -> 45747
A5: # | B5: Income Statement
B6: Sales | C6: =IFERROR('Data Sheet'!B17,0) -> 14271.49 | D6: =IFERROR('Data Sheet'!C17,0) -> 15061.99 | E6: =IFERROR('Data Sheet'!D17,0) -> 16824.55 | F6: =IFERROR('Data Sheet'!E17,0) -> 19240.13 | G6: =IFERROR('Data Sheet'!F17,0) -> 20211.25 | H6: =IFERROR('Data Sheet'!G17,0) -> 21712.79 | I6: =IFERROR('Data Sheet'!H17,0) -> 29101.28 | J6: =IFERROR('Data Sheet'!I17,0) -> 34488.59 | ... L6: =IFERROR('Data Sheet'!K17,0) -> 33905.62
B7: Sales Growth % | C7: - | D7: =D6/C6-1 -> 0.055390152 | E7: =E6/D6-1 -> 0.11702039 | F7: =F6/E6-1 -> 0.14357472 | G7: =G6/F6-1 -> 0.050473671 | H7: =H6/G6-1 -> 0.074292288 | I7: =I6/H6-1 -> 0.34028285 | J7: =J6/I6-1 -> 0.18512278 | K7: =K6/J6-1 -> 0.029173127 | L7: =L6/K6-1 -> -0.044770308
B9: COGS | C9: =IFERROR(SUM('Data Sheet'!B18,'Data Sheet'!B20:B22)-1*'Data Sheet'!B19,0) -> 9413.84 | D9: =IFERROR(SUM('Data Sheet'!C18,'Data Sheet'!C20:C22)-1*'Data Sheet'!C19,0) -> 9732.66 | E9: =IFERROR(SUM('Data Sheet'!D18,'Data Sheet'!D20:D22)-1*'Data Sheet'!D19,0) -> 11194.17 | F9: =IFERROR(SUM('Data Sheet'!E18,'Data Sheet'!E20:E22)-1*'Data Sheet'!E19,0) -> 12905.81 | G9: =IFERROR(SUM('Data Sheet'!F18,'Data Sheet'!F20:F22)-1*'Data Sheet'!F19,0) -> 13158.02 | H9: =IFERROR(SUM('Data Sheet'!G18,'Data Sheet'!G20:G22)-1*'Data Sheet'!G19,0) -> 14035.07 | I9: =IFERROR(SUM('Data Sheet'!H18,'Data Sheet'!H20:H22)-1*'Data Sheet'!H19,0) -> 20590.57 | J9: =IFERROR(SUM('Data Sheet'!I18,'Data Sheet'!I20:I22)-1*'Data Sheet'!I19,0) -> 23766.7 | ... L9: =IFERROR(SUM('Data Sheet'!K18,'Data Sheet'!K20:K22)-1*'Data Sheet'!K19,0) -> 22741.27
B10: COGS % of Sales | C10: =C9/C6 -> 0.65962559 | D10: =D9/D6 -> 0.64617358 | E10: =E9/E6 -> 0.66534736 | F10: =F9/F6 -> 0.67077561 | G10: =G9/G6 -> 0.65102455 | H10: =H9/H6 -> 0.64639643 | I10: =I9/I6 -> 0.7075486 | J10: =J9/J6 -> 0.68911776 | ... L10: =L9/L6 -> 0.67072273
B12: Gross Profit | C12: =C6-C9 -> 4857.65 | D12: =D6-D9 -> 5329.33 | E12: =E6-E9 -> 5630.38 | F12: =F6-F9 -> 6334.32 | G12: =G6-G9 -> 7053.23 | H12: =H6-H9 -> 7677.72 | I12: =I6-I9 -> 8510.71 | J12: =J6-J9 -> 10721.89 | ... L12: =L6-L9 -> 11164.35
B13: Gross Margins | C13: =C12/C6 -> 0.34037441 | D13: =D12/D6 -> 0.35382642 | E13: =E12/E6 -> 0.33465264 | F13: =F12/F6 -> 0.32922439 | G13: =G12/G6 -> 0.34897545 | H13: =H12/H6 -> 0.35360357 | I13: =I12/I6 -> 0.2924514 | J13: =J12/J6 -> 0.31088224 | ... L13: =L12/L6 -> 0.32927727
B15: Selling & General Expenses | C15: =IFERROR(SUM('Data Sheet'!B23:B24),0) -> 2132.61 | D15: =IFERROR(SUM('Data Sheet'!C23:C24),0) -> 2335.57 | E15: =IFERROR(SUM('Data Sheet'!D23:D24),0) -> 2426.37 | F15: =IFERROR(SUM('Data Sheet'!E23:E24),0) -> 2569.38 | G15: =IFERROR(SUM('Data Sheet'!F23:F24),0) -> 2896.41 | H15: =IFERROR(SUM('Data Sheet'!G23:G24),0) -> 2822.12 | I15: =IFERROR(SUM('Data Sheet'!H23:H24),0) -> 3707.1 | J15: =IFERROR(SUM('Data Sheet'!I23:I24),0) -> 4462.05 | ... L15: =IFERROR(SUM('Data Sheet'!K23:K24),0) -> 5158.14
B16: S&G Exp % of Sales | C16: =C15/C6 -> 0.14943149 | D16: =D15/D6 -> 0.15506384 | E16: =E15/E6 -> 0.14421604 | F16: =F15/F6 -> 0.13354276 | G16: =G15/G6 -> 0.14330682 | H16: =H15/H6 -> 0.12997501 | I16: =I15/I6 -> 0.12738615 | J16: =J15/J6 -> 0.12937757 | ... L16: =L15/L6 -> 0.1521323
B18: EBITDA | C18: =C12-C15 -> 2725.04 | D18: =D12-D15 -> 2993.76 | E18: =E12-E15 -> 3204.01 | F18: =F12-F15 -> 3764.94 | G18: =G12-G15 -> 4156.82 | H18: =H12-H15 -> 4855.6 | I18: =I12-I15 -> 4803.61 | J18: =J12-J15 -> 6259.84 | ... L18: =L12-L15 -> 6006.21
B19: EBITDA % of Sales | C19: =C18/C6 -> 0.19094292 | D19: =D18/D6 -> 0.19876258 | E19: =E18/E6 -> 0.19043659 | F19: =F18/F6 -> 0.19568163 | G19: =G18/G6 -> 0.20566863 | H19: =H18/H6 -> 0.22362856 | I19: =I18/I6 -> 0.16506525 | J19: =J18/J6 -> 0.18150467 | ... L19: =L18/L6 -> 0.17714497
B21: Interest | C21: =IFERROR('Data Sheet'!B27,0) -> 49 | D21: =IFERROR('Data Sheet'!C27,0) -> 37.33 | E21: =IFERROR('Data Sheet'!D27,0) -> 41.47 | F21: =IFERROR('Data Sheet'!E27,0) -> 110.47 | G21: =IFERROR('Data Sheet'!F27,0) -> 102.33 | H21: =IFERROR('Data Sheet'!G27,0) -> 91.63 | I21: =IFERROR('Data Sheet'!H27,0) -> 95.41 | J21: =IFERROR('Data Sheet'!I27,0) -> 144.45 | ... L21: =IFERROR('Data Sheet'!K27,0) -> 227.02
B22: Interest % of Sales | C22: =C21/C6 -> 0.0034334187 | D22: =D21/D6 -> 0.0024784242 | E22: =E21/E6 -> 0.0024648505 | F22: =F21/F6 -> 0.0057416452 | G22: =G21/G6 -> 0.0050630218 | H22: =H21/H6 -> 0.0042200933 | I22: =I21/I6 -> 0.0032785499 | J22: =J21/J6 -> 0.0041883417 | ... L22: =L21/L6 -> 0.0066956451
B24: Depriciation | C24: =IFERROR('Data Sheet'!B26,0) -> 275.58 | D24: =IFERROR('Data Sheet'!C26,0) -> 334.79 | E24: =IFERROR('Data Sheet'!D26,0) -> 360.47 | F24: =IFERROR('Data Sheet'!E26,0) -> 622.14 | G24: =IFERROR('Data Sheet'!F26,0) -> 780.5 | H24: =IFERROR('Data Sheet'!G26,0) -> 791.27 | I24: =IFERROR('Data Sheet'!H26,0) -> 816.36 | J24: =IFERROR('Data Sheet'!I26,0) -> 858.02 | ... L24: =IFERROR('Data Sheet'!K26,0) -> 1026.34
B25: Depriciation % of Sales | C25: =C24/C6 -> 0.019309827 | D25: =D24/D6 -> 0.022227475 | E25: =E24/E6 -> 0.021425239 | F25: =F24/F6 -> 0.03233554 | G25: =G24/G6 -> 0.038617107 | H25: =H24/H6 -> 0.036442576 | I25: =I24/I6 -> 0.028052374 | J25: =J24/J6 -> 0.024878373 | ... L25: =L24/L6 -> 0.030270498
B27: EBIT | C27: =C18-C24 -> 2449.46 | D27: =D18-D24 -> 2658.97 | E27: =E18-E24 -> 2843.54 | F27: =F18-F24 -> 3142.8 | G27: =G18-G24 -> 3376.32 | H27: =H18-H24 -> 4064.33 | I27: =I18-I24 -> 3987.25 | J27: =J18-J24 -> 5401.82 | ... L27: =L18-L24 -> 4979.87
B28: EBIT % of Sales | C28: =IFERROR(C27/C6,0) -> 0.1716331 | D28: =IFERROR(D27/D6,0) -> 0.17653511 | E28: =IFERROR(E27/E6,0) -> 0.16901136 | F28: =IFERROR(F27/F6,0) -> 0.16334609 | G28: =IFERROR(G27/G6,0) -> 0.16705152 | H28: =IFERROR(H27/H6,0) -> 0.18718599 | I28: =IFERROR(I27/I6,0) -> 0.13701287 | J28: =IFERROR(J27/J6,0) -> 0.15662629 | ... L28: =IFERROR(L27/L6,0) -> 0.14687447
B30: EBT | C30: =IFERROR(C18-SUM(C21,C24),0) -> 2400.46 | D30: =IFERROR(D18-SUM(D21,D24),0) -> 2621.64 | E30: =IFERROR(E18-SUM(E21,E24),0) -> 2802.07 | F30: =IFERROR(F18-SUM(F21,F24),0) -> 3032.33 | G30: =IFERROR(G18-SUM(G21,G24),0) -> 3273.99 | H30: =IFERROR(H18-SUM(H21,H24),0) -> 3972.7 | I30: =IFERROR(I18-SUM(I21,I24),0) -> 3891.84 | J30: =IFERROR(J18-SUM(J21,J24),0) -> 5257.37 | ... L30: =IFERROR(L18-SUM(L21,L24),0) -> 4752.85
B31: EBT % of Sales | C31: =C30/C6 -> 0.16819968 | D31: =D30/D6 -> 0.17405668 | E31: =E30/E6 -> 0.1665465 | F31: =F30/F6 -> 0.15760444 | G31: =G30/G6 -> 0.1619885 | H31: =H30/H6 -> 0.18296589 | I31: =I30/I6 -> 0.13373432 | J31: =J30/J6 -> 0.15243795 | ... L31: =L30/L6 -> 0.14017883
B33: Tax | C33: =IFERROR('Data Sheet'!B29,0) -> 844.49 | D33: =IFERROR('Data Sheet'!C29,0) -> 943.29 | E33: =IFERROR('Data Sheet'!D29,0) -> 1040.96 | F33: =IFERROR('Data Sheet'!E29,0) -> 1098.06 | G33: =IFERROR('Data Sheet'!F29,0) -> 854.85 | H33: =IFERROR('Data Sheet'!G29,0) -> 1097.6 | I33: =IFERROR('Data Sheet'!H29,0) -> 1102.91 | J33: =IFERROR('Data Sheet'!I29,0) -> 1493.5 | ... L33: =IFERROR('Data Sheet'!K29,0) -> 1393.36
B34: Effective Tax Rate | C34: =C33/C30 -> 0.3518034 | D34: =D33/D30 -> 0.35980913 | E34: =E33/E30 -> 0.37149679 | F34: =F33/F30 -> 0.36211758 | G34: =G33/G30 -> 0.26110342 | H34: =H33/H30 -> 0.27628565 | I34: =I33/I30 -> 0.28339038 | J34: =J33/J30 -> 0.2840774 | ... L34: =L33/L30 -> 0.29316305
B36: Net Profit | C36: =C30-C33 -> 1555.97 | D36: =D30-D33 -> 1678.35 | E36: =E30-E33 -> 1761.11 | F36: =F30-F33 -> 1934.27 | G36: =G30-G33 -> 2419.14 | H36: =H30-H33 -> 2875.1 | I36: =I30-I33 -> 2788.93 | J36: =J30-J33 -> 3763.87 | ... L36: =L30-L33 -> 3359.49
B37: Net Margins | C37: =C36/C6 -> 0.10902646 | D37: =D36/D6 -> 0.1114295 | E37: =E36/E6 -> 0.10467501 | F37: =F36/F6 -> 0.1005331 | G37: =G36/G6 -> 0.11969275 | H37: =H36/H6 -> 0.13241504 | I37: =I36/I6 -> 0.095835303 | J37: =J36/J6 -> 0.10913377 | ... L37: =L36/L6 -> 0.099083574
B39: No. of Equity Shares | C39: =IFERROR('Data Sheet'!B93,0) -> 95.92 | D39: =IFERROR('Data Sheet'!C93,0) -> 95.92 | E39: =IFERROR('Data Sheet'!D93,0) -> 95.92 | F39: =IFERROR('Data Sheet'!E93,0) -> 95.92 | G39: =IFERROR('Data Sheet'!F93,0) -> 95.92 | H39: =IFERROR('Data Sheet'!G93,0) -> 95.92 | I39: =IFERROR('Data Sheet'!H93,0) -> 95.92 | J39: =IFERROR('Data Sheet'!I93,0) -> 95.92 | ... L39: =IFERROR('Data Sheet'!K93,0) -> 95.92
B41: EPS | C41: =IFERROR(C36/C39,0) -> 16.221539 | D41: =IFERROR(D36/D39,0) -> 17.497394 | E41: =IFERROR(E36/E39,0) -> 18.360196 | F41: =IFERROR(F36/F39,0) -> 20.16545 | G41: =IFERROR(G36/G39,0) -> 25.220392 | H41: =IFERROR(H36/H39,0) -> 29.973937 | I41: =IFERROR(I36/I39,0) -> 29.075584 | J41: =IFERROR(J36/J39,0) -> 39.239679 | ... L41: =IFERROR(L36/L39,0) -> 35.023874
B42: EPS Growth % | C42: - | D42: =IFERROR(D41/C41,0) -> 1.0786519 | E42: =IFERROR(E41/D41,0) -> 1.0493103 | F42: =IFERROR(F41/E41,0) -> 1.0983244 | G42: =IFERROR(G41/F41,0) -> 1.2506734 | H42: =IFERROR(H41/G41,0) -> 1.1884802 | I42: =IFERROR(I41/H41,0) -> 0.97002887 | J42: =IFERROR(J41/I41,0) -> 1.3495749 | K42: =IFERROR(K41/J41,0) -> 1.2584733 | L42: =IFERROR(L41/K41,0) -> 0.70924245
B44: Divided per Share | C44: =IFERROR('Data Sheet'!B31/HistoricalFS!C39,0) -> 7.5 | D44: =IFERROR('Data Sheet'!C31/HistoricalFS!D39,0) -> 10.300042 | E44: =IFERROR('Data Sheet'!D31/HistoricalFS!E39,0) -> 8.6999583 | F44: =IFERROR('Data Sheet'!E31/HistoricalFS!F39,0) -> 10.5 | G44: =IFERROR('Data Sheet'!F31/HistoricalFS!G39,0) -> 12 | H44: =IFERROR('Data Sheet'!G31/HistoricalFS!H39,0) -> 17.849979 | I44: =IFERROR('Data Sheet'!H31/HistoricalFS!I39,0) -> 19.150021 | J44: =IFERROR('Data Sheet'!I31/HistoricalFS!J39,0) -> 25.650021 | ... L44: =IFERROR('Data Sheet'!K31/HistoricalFS!L39,0) -> 24.800042
B45: Dividend Payout Ratio | C45: =IFERROR(C44/C41,0) -> 0.46234825 | D45: =IFERROR(D44/D41,0) -> 0.58866148 | E45: =IFERROR(E44/E41,0) -> 0.47384888 | F45: =IFERROR(F44/F41,0) -> 0.52069256 | G45: =IFERROR(G44/G41,0) -> 0.47580545 | H45: =IFERROR(H44/H41,0) -> 0.59551668 | I45: =IFERROR(I44/I41,0) -> 0.65862894 | J45: =IFERROR(J44/J41,0) -> 0.65367561 | ... L45: =IFERROR(L44/L41,0) -> 0.70808962
B47: Retained Earnings | C47: =IFERROR(IF(C41>C44,1-C45,0),0) -> 0.53765175 | D47: =IFERROR(IF(D41>D44,1-D45,0),0) -> 0.41133852 | E47: =IFERROR(IF(E41>E44,1-E45,0),0) -> 0.52615112 | F47: =IFERROR(IF(F41>F44,1-F45,0),0) -> 0.47930744 | G47: =IFERROR(IF(G41>G44,1-G45,0),0) -> 0.52419455 | H47: =IFERROR(IF(H41>H44,1-H45,0),0) -> 0.40448332 | I47: =IFERROR(IF(I41>I44,1-I45,0),0) -> 0.34137106 | J47: =IFERROR(IF(J41>J44,1-J45,0),0) -> 0.34632439 | ... L47: =IFERROR(IF(L41>L44,1-L45,0),0) -> 0.29191038
A49: # | B49: Balance Sheet
B50: Equity Share Capital | C50: =IFERROR('Data Sheet'!B57,0) -> 95.92 | D50: =IFERROR('Data Sheet'!C57,0) -> 95.92 | E50: =IFERROR('Data Sheet'!D57,0) -> 95.92 | F50: =IFERROR('Data Sheet'!E57,0) -> 95.92 | G50: =IFERROR('Data Sheet'!F57,0) -> 95.92 | H50: =IFERROR('Data Sheet'!G57,0) -> 95.92 | I50: =IFERROR('Data Sheet'!H57,0) -> 95.92 | J50: =IFERROR('Data Sheet'!I57,0) -> 95.92 | ... L50: =IFERROR('Data Sheet'!K57,0) -> 95.92
B51: Reserves | C51: =IFERROR('Data Sheet'!B58,0) -> 6428.9 | D51: =IFERROR('Data Sheet'!C58,0) -> 7507.97 | E51: =IFERROR('Data Sheet'!D58,0) -> 8314.31 | F51: =IFERROR('Data Sheet'!E58,0) -> 9374.63 | G51: =IFERROR('Data Sheet'!F58,0) -> 10034.24 | H51: =IFERROR('Data Sheet'!G58,0) -> 12710.37 | I51: =IFERROR('Data Sheet'!H58,0) -> 13715.64 | J51: =IFERROR('Data Sheet'!I58,0) -> 15896.31 | ... L51: =IFERROR('Data Sheet'!K58,0) -> 19303.89
B52: Borrowings | C52: =IFERROR('Data Sheet'!B59,0) -> 323.29 | D52: =IFERROR('Data Sheet'!C59,0) -> 560.34 | E52: =IFERROR('Data Sheet'!D59,0) -> 533.43 | F52: =IFERROR('Data Sheet'!E59,0) -> 1319.6 | G52: =IFERROR('Data Sheet'!F59,0) -> 1118.5 | H52: =IFERROR('Data Sheet'!G59,0) -> 1093.12 | I52: =IFERROR('Data Sheet'!H59,0) -> 1586.88 | J52: =IFERROR('Data Sheet'!I59,0) -> 1932.62 | ... L52: =IFERROR('Data Sheet'!K59,0) -> 2290.29
B53: Other Liabilities | C53: =IFERROR('Data Sheet'!B60,0) -> 3710.92 | D53: =IFERROR('Data Sheet'!C60,0) -> 4240.96 | E53: =IFERROR('Data Sheet'!D60,0) -> 4819.82 | F53: =IFERROR('Data Sheet'!E60,0) -> 5458.69 | G53: =IFERROR('Data Sheet'!F60,0) -> 4889.31 | H53: =IFERROR('Data Sheet'!G60,0) -> 6455.93 | I53: =IFERROR('Data Sheet'!H60,0) -> 7559.99 | J53: =IFERROR('Data Sheet'!I60,0) -> 7854.48 | ... L53: =IFERROR('Data Sheet'!K60,0) -> 8665.15
B54: Total Liabilities | C54: =SUM(C50:C53) -> 10559.03 | D54: =SUM(D50:D53) -> 12405.19 | E54: =SUM(E50:E53) -> 13763.48 | F54: =SUM(F50:F53) -> 16248.84 | G54: =SUM(G50:G53) -> 16137.97 | H54: =SUM(H50:H53) -> 20355.34 | I54: =SUM(I50:I53) -> 22958.43 | J54: =SUM(J50:J53) -> 25779.33 | ... L54: =SUM(L50:L53) -> 30355.25
B56: Fixed Assets Net Block | C56: =IFERROR('Data Sheet'!B62,0) -> 3416.35 | D56: =IFERROR('Data Sheet'!C62,0) -> 3303.74 | E56: =IFERROR('Data Sheet'!D62,0) -> 3732.24 | F56: =IFERROR('Data Sheet'!E62,0) -> 6496.56 | G56: =IFERROR('Data Sheet'!F62,0) -> 6272.31 | H56: =IFERROR('Data Sheet'!G62,0) -> 5858.52 | I56: =IFERROR('Data Sheet'!H62,0) -> 5519.06 | J56: =IFERROR('Data Sheet'!I62,0) -> 5770.46 | ... L56: =IFERROR('Data Sheet'!K62,0) -> 9220.1
B57: Capital Work in Progress | C57: =IFERROR('Data Sheet'!B63,0) -> 106.59 | D57: =IFERROR('Data Sheet'!C63,0) -> 257.54 | E57: =IFERROR('Data Sheet'!D63,0) -> 1405.11 | F57: =IFERROR('Data Sheet'!E63,0) -> 209.67 | G57: =IFERROR('Data Sheet'!F63,0) -> 140.24 | H57: =IFERROR('Data Sheet'!G63,0) -> 182.98 | I57: =IFERROR('Data Sheet'!H63,0) -> 426.43 | J57: =IFERROR('Data Sheet'!I63,0) -> 1019.59 | ... L57: =IFERROR('Data Sheet'!K63,0) -> 1254.49
B58: Investments | C58: =IFERROR('Data Sheet'!B64,0) -> 2712.13 | D58: =IFERROR('Data Sheet'!C64,0) -> 2651.99 | E58: =IFERROR('Data Sheet'!D64,0) -> 2140.7 | F58: =IFERROR('Data Sheet'!E64,0) -> 2568.58 | G58: =IFERROR('Data Sheet'!F64,0) -> 2018.85 | H58: =IFERROR('Data Sheet'!G64,0) -> 4736.8 | I58: =IFERROR('Data Sheet'!H64,0) -> 3247.53 | J58: =IFERROR('Data Sheet'!I64,0) -> 4261.71 | ... L58: =IFERROR('Data Sheet'!K64,0) -> 4724.75
...

Sheet Ratio Analysis
B2: ="Ratio Analysis - "&'Data Sheet'!B1 -> Ratio Analysis - ASIAN PAINTS LTD
B3: Years | C3: ='[1]Data Sheet'!B16 -> 42460 | D3: ='[1]Data Sheet'!C16 -> 42825 | E3: ='[1]Data Sheet'!D16 -> 43190 | F3: ='[1]Data Sheet'!E16 -> 43555 | G3: ='[1]Data Sheet'!F16 -> 43921 | H3: ='[1]Data Sheet'!G16 -> 44286 | I3: ='[1]Data Sheet'!H16 -> 44651 | J3: ='[1]Data Sheet'!I16 -> 45016 | ... L3: ='[1]Data Sheet'!K16 -> 45747 | M3: Trend | N3: Mean | O3: Median
B5: Sales Growth | D5: =IFERROR(HistoricalFS!D7,0) -> 0.055390152 | E5: =IFERROR(HistoricalFS!E7,0) -> 0.11702039 | F5: =IFERROR(HistoricalFS!F7,0) -> 0.14357472 | G5: =IFERROR(HistoricalFS!G7,0) -> 0.050473671 | H5: =IFERROR(HistoricalFS!H7,0) -> 0.074292288 | I5: =IFERROR(HistoricalFS!I7,0) -> 0.34028285 | J5: =IFERROR(HistoricalFS!J7,0) -> 0.18512278 | K5: =IFERROR(HistoricalFS!K7,0) -> 0.029173127 | L5: =IFERROR(HistoricalFS!L7,0) -> -0.044770308 | N5: =IFERROR(AVERAGE(D5:L5),0) -> 0.10561774 | O5: =IFERROR(MEDIAN(D5:L5),0) -> 0.074292288
B6: EBITDA Growth | D6: =IFERROR(HistoricalFS!D18/HistoricalFS!C18-1,0) -> 0.098611397 | E6: =IFERROR(HistoricalFS!E18/HistoricalFS!D18-1,0) -> 0.070229411 | F6: =IFERROR(HistoricalFS!F18/HistoricalFS!E18-1,0) -> 0.17507124 | G6: =IFERROR(HistoricalFS!G18/HistoricalFS!F18-1,0) -> 0.10408665 | H6: =IFERROR(HistoricalFS!H18/HistoricalFS!G18-1,0) -> 0.16810446 | I6: =IFERROR(HistoricalFS!I18/HistoricalFS!H18-1,0) -> -0.010707225 | J6: =IFERROR(HistoricalFS!J18/HistoricalFS!I18-1,0) -> 0.30315325 | K6: =IFERROR(HistoricalFS!K18/HistoricalFS!J18-1,0) -> 0.21168912 | L6: =IFERROR(HistoricalFS!L18/HistoricalFS!K18-1,0) -> -0.20814425 | N6: =IFERROR(AVERAGE(D6:L6),0) -> 0.10134378 | O6: =IFERROR(MEDIAN(D6:L6),0) -> 0.10408665
B7: EBIT Growth | D7: =IFERROR(HistoricalFS!D27/HistoricalFS!C27-1,0) -> 0.085533138 | E7: =IFERROR(HistoricalFS!E27/HistoricalFS!D27-1,0) -> 0.069414096 | F7: =IFERROR(HistoricalFS!F27/HistoricalFS!E27-1,0) -> 0.10524206 | G7: =IFERROR(HistoricalFS!G27/HistoricalFS!F27-1,0) -> 0.074303169 | H7: =IFERROR(HistoricalFS!H27/HistoricalFS!G27-1,0) -> 0.20377512 | I7: =IFERROR(HistoricalFS!I27/HistoricalFS!H27-1,0) -> -0.018964995 | J7: =IFERROR(HistoricalFS!J27/HistoricalFS!I27-1,0) -> 0.35477334 | K7: =IFERROR(HistoricalFS!K27/HistoricalFS!J27-1,0) -> 0.24624293 | L7: =IFERROR(HistoricalFS!L27/HistoricalFS!K27-1,0) -> -0.26026667 | N7: =IFERROR(AVERAGE(D7:L7),0) -> 0.095561354 | O7: =IFERROR(MEDIAN(D7:L7),0) -> 0.085533138
B8: EBT Growth | D8: =IFERROR(HistoricalFS!D30/HistoricalFS!C30-1,0) -> 0.092140673 | E8: =IFERROR(HistoricalFS!E30/HistoricalFS!D30-1,0) -> 0.068823332 | F8: =IFERROR(HistoricalFS!F30/HistoricalFS!E30-1,0) -> 0.082174964 | G8: =IFERROR(HistoricalFS!G30/HistoricalFS!F30-1,0) -> 0.079694492 | H8: =IFERROR(HistoricalFS!H30/HistoricalFS!G30-1,0) -> 0.21341238 | I8: =IFERROR(HistoricalFS!I30/HistoricalFS!H30-1,0) -> -0.020353915 | J8: =IFERROR(HistoricalFS!J30/HistoricalFS!I30-1,0) -> 0.35087003 | K8: =IFERROR(HistoricalFS!K30/HistoricalFS!J30-1,0) -> 0.24145913 | L8: =IFERROR(HistoricalFS!L30/HistoricalFS!K30-1,0) -> -0.27179587 | N8: =IFERROR(AVERAGE(D8:L8),0) -> 0.092936135 | O8: =IFERROR(MEDIAN(D8:L8),0) -> 0.082174964
B9: Net Profit Growth | D9: =IFERROR(HistoricalFS!D36/HistoricalFS!C36-1,0) -> 0.078651902 | E9: =IFERROR(HistoricalFS!E36/HistoricalFS!D36-1,0) -> 0.049310335 | F9: =IFERROR(HistoricalFS!F36/HistoricalFS!E36-1,0) -> 0.098324352 | G9: =IFERROR(HistoricalFS!G36/HistoricalFS!F36-1,0) -> 0.25067338 | H9: =IFERROR(HistoricalFS!H36/HistoricalFS!G36-1,0) -> 0.1884802 | I9: =IFERROR(HistoricalFS!I36/HistoricalFS!H36-1,0) -> -0.029971131 | J9: =IFERROR(HistoricalFS!J36/HistoricalFS!I36-1,0) -> 0.34957493 | K9: =IFERROR(HistoricalFS!K36/HistoricalFS!J36-1,0) -> 0.25847333 | L9: =IFERROR(HistoricalFS!L36/HistoricalFS!K36-1,0) -> -0.29075755 | N9: =IFERROR(AVERAGE(D9:L9),0) -> 0.10586219 | O9: =IFERROR(MEDIAN(D9:L9),0) -> 0.098324352
B10: Dividend Growth | D10: =IFERROR(HistoricalFS!D44/HistoricalFS!C44-1,0) -> 0.37333889 | E10: =IFERROR(HistoricalFS!E44/HistoricalFS!D44-1,0) -> -0.15534727 | F10: =IFERROR(HistoricalFS!F44/HistoricalFS!E44-1,0) -> 0.20690234 | G10: =IFERROR(HistoricalFS!G44/HistoricalFS!F44-1,0) -> 0.14285714 | H10: =IFERROR(HistoricalFS!H44/HistoricalFS!G44-1,0) -> 0.48749826 | I10: =IFERROR(HistoricalFS!I44/HistoricalFS!H44-1,0) -> 0.072831553 | J10: =IFERROR(HistoricalFS!J44/HistoricalFS!I44-1,0) -> 0.33942522 | K10: =IFERROR(HistoricalFS!K44/HistoricalFS!J44-1,0) -> 0.29824618 | L10: =IFERROR(HistoricalFS!L44/HistoricalFS!K44-1,0) -> -0.25525494 | N10: =IFERROR(AVERAGE(D10:L10),0) -> 0.16783304 | O10: =IFERROR(MEDIAN(D10:L10),0) -> 0.20690234
B12: Gross Margin | C12: =IFERROR(HistoricalFS!C13,0) -> 0.34037441 | D12: =IFERROR(HistoricalFS!D13,0) -> 0.35382642 | E12: =IFERROR(HistoricalFS!E13,0) -> 0.33465264 | F12: =IFERROR(HistoricalFS!F13,0) -> 0.32922439 | G12: =IFERROR(HistoricalFS!G13,0) -> 0.34897545 | H12: =IFERROR(HistoricalFS!H13,0) -> 0.35360357 | I12: =IFERROR(HistoricalFS!I13,0) -> 0.2924514 | J12: =IFERROR(HistoricalFS!J13,0) -> 0.31088224 | ... L12: =IFERROR(HistoricalFS!L13,0) -> 0.32927727 | N12: =IFERROR(AVERAGE(C12:L12),0) -> 0.33450028 | O12: =IFERROR(MEDIAN(C12:L12),0) -> 0.33751352
B13: EBITA Margin | C13: =IFERROR(HistoricalFS!C19,0) -> 0.19094292 | D13: =IFERROR(HistoricalFS!D19,0) -> 0.19876258 | E13: =IFERROR(HistoricalFS!E19,0) -> 0.19043659 | F13: =IFERROR(HistoricalFS!F19,0) -> 0.19568163 | G13: =IFERROR(HistoricalFS!G19,0) -> 0.20566863 | H13: =IFERROR(HistoricalFS!H19,0) -> 0.22362856 | I13: =IFERROR(HistoricalFS!I19,0) -> 0.16506525 | J13: =IFERROR(HistoricalFS!J19,0) -> 0.18150467 | ... L13: =IFERROR(HistoricalFS!L19,0) -> 0.17714497 | N13: =IFERROR(AVERAGE(C13:L13),0) -> 0.19425289 | O13: =IFERROR(MEDIAN(C13:L13),0) -> 0.19331228
B14: EBIT Margin | C14: =IFERROR(HistoricalFS!C28,0) -> 0.1716331 | D14: =IFERROR(HistoricalFS!D28,0) -> 0.17653511 | E14: =IFERROR(HistoricalFS!E28,0) -> 0.16901136 | F14: =IFERROR(HistoricalFS!F28,0) -> 0.16334609 | G14: =IFERROR(HistoricalFS!G28,0) -> 0.16705152 | H14: =IFERROR(HistoricalFS!H28,0) -> 0.18718599 | I14: =IFERROR(HistoricalFS!I28,0) -> 0.13701287 | J14: =IFERROR(HistoricalFS!J28,0) -> 0.15662629 | ... L14: =IFERROR(HistoricalFS!L28,0) -> 0.14687447 | N14: =IFERROR(AVERAGE(C14:L14),0) -> 0.16649382 | O14: =IFERROR(MEDIAN(C14:L14),0) -> 0.16803144
B15: EBT Margin | C15: =IFERROR(HistoricalFS!C31,0) -> 0.16819968 | D15: =IFERROR(HistoricalFS!D31,0) -> 0.17405668 | E15: =IFERROR(HistoricalFS!E31,0) -> 0.1665465 | F15: =IFERROR(HistoricalFS!F31,0) -> 0.15760444 | G15: =IFERROR(HistoricalFS!G31,0) -> 0.1619885 | H15: =IFERROR(HistoricalFS!H31,0) -> 0.18296589 | I15: =IFERROR(HistoricalFS!I31,0) -> 0.13373432 | J15: =IFERROR(HistoricalFS!J31,0) -> 0.15243795 | ... L15: =IFERROR(HistoricalFS!L31,0) -> 0.14017883 | N15: =IFERROR(AVERAGE(C15:L15),0) -> 0.16215939 | O15: =IFERROR(MEDIAN(C15:L15),0) -> 0.1642675
B16: Net Profit Margin | C16: =IFERROR(HistoricalFS!C37,0) -> 0.10902646 | D16: =IFERROR(HistoricalFS!D37,0) -> 0.1114295 | E16: =IFERROR(HistoricalFS!E37,0) -> 0.10467501 | F16: =IFERROR(HistoricalFS!F37,0) -> 0.1005331 | G16: =IFERROR(HistoricalFS!G37,0) -> 0.11969275 | H16: =IFERROR(HistoricalFS!H37,0) -> 0.13241504 | I16: =IFERROR(HistoricalFS!I37,0) -> 0.095835303 | J16: =IFERROR(HistoricalFS!J37,0) -> 0.10913377 | ... L16: =IFERROR(HistoricalFS!L37,0) -> 0.099083574 | N16: =IFERROR(AVERAGE(C16:L16),0) -> 0.11152733 | O16: =IFERROR(MEDIAN(C16:L16),0) -> 0.10908012
B18: Sales Expenses % of sales | C18: =IFERROR(HistoricalFS!C16,0) -> 0.14943149 | D18: =IFERROR(HistoricalFS!D16,0) -> 0.15506384 | E18: =IFERROR(HistoricalFS!E16,0) -> 0.14421604 | F18: =IFERROR(HistoricalFS!F16,0) -> 0.13354276 | G18: =IFERROR(HistoricalFS!G16,0) -> 0.14330682 | H18: =IFERROR(HistoricalFS!H16,0) -> 0.12997501 | I18: =IFERROR(HistoricalFS!I16,0) -> 0.12738615 | J18: =IFERROR(HistoricalFS!J16,0) -> 0.12937757 | ... L18: =IFERROR(HistoricalFS!L16,0) -> 0.1521323 | N18: =IFERROR(AVERAGE(C18:L18),0) -> 0.14024739 | O18: =IFERROR(MEDIAN(C18:L18),0) -> 0.14067436
B19: Depriciation % of sales | C19: =IFERROR(HistoricalFS!C25,0) -> 0.019309827 | D19: =IFERROR(HistoricalFS!D25,0) -> 0.022227475 | E19: =IFERROR(HistoricalFS!E25,0) -> 0.021425239 | F19: =IFERROR(HistoricalFS!F25,0) -> 0.03233554 | G19: =IFERROR(HistoricalFS!G25,0) -> 0.038617107 | H19: =IFERROR(HistoricalFS!H25,0) -> 0.036442576 | I19: =IFERROR(HistoricalFS!I25,0) -> 0.028052374 | J19: =IFERROR(HistoricalFS!J25,0) -> 0.024878373 | ... L19: =IFERROR(HistoricalFS!L25,0) -> 0.030270498 | N19: =IFERROR(AVERAGE(C19:L19),0) -> 0.027759074 | O19: =IFERROR(MEDIAN(C19:L19),0) -> 0.026465374
B20: Operating Income % of sales | C20: =C14 -> 0.1716331 | D20: =D14 -> 0.17653511 | E20: =E14 -> 0.16901136 | F20: =F14 -> 0.16334609 | G20: =G14 -> 0.16705152 | H20: =H14 -> 0.18718599 | I20: =I14 -> 0.13701287 | J20: =J14 -> 0.15662629 | ... L20: =L14 -> 0.14687447 | N20: =IFERROR(AVERAGE(C20:L20),0) -> 0.16649382 | O20: =IFERROR(MEDIAN(C20:L20),0) -> 0.16803144
B22: Return on Capital Employed | C22: =IFERROR(HistoricalFS!C27/SUM(HistoricalFS!C50:C52),0) -> 0.35768409 | D22: =IFERROR(HistoricalFS!D27/SUM(HistoricalFS!D50:D52),0) -> 0.32568534 | E22: =IFERROR(HistoricalFS!E27/SUM(HistoricalFS!E50:E52),0) -> 0.31793919 | F22: =IFERROR(HistoricalFS!F27/SUM(HistoricalFS!F50:F52),0) -> 0.29126565 | G22: =IFERROR(HistoricalFS!G27/SUM(HistoricalFS!G50:G52),0) -> 0.30015308 | H22: =IFERROR(HistoricalFS!H27/SUM(HistoricalFS!H50:H52),0) -> 0.29241025 | I22: =IFERROR(HistoricalFS!I27/SUM(HistoricalFS!I50:I52),0) -> 0.25893857 | J22: =IFERROR(HistoricalFS!J27/SUM(HistoricalFS!J50:J52),0) -> 0.30135929 | ... L22: =IFERROR(HistoricalFS!L27/SUM(HistoricalFS!L50:L52),0) -> 0.22959184 | N22: =IFERROR(AVERAGE(C22:L22),0) -> 0.29925334 | O22: =IFERROR(MEDIAN(C22:L22),0) -> 0.30075619
B23: Retained Earnings % | C23: =IFERROR(HistoricalFS!C47,0) -> 0.53765175 | D23: =IFERROR(HistoricalFS!D47,0) -> 0.41133852 | E23: =IFERROR(HistoricalFS!E47,0) -> 0.52615112 | F23: =IFERROR(HistoricalFS!F47,0) -> 0.47930744 | G23: =IFERROR(HistoricalFS!G47,0) -> 0.52419455 | H23: =IFERROR(HistoricalFS!H47,0) -> 0.40448332 | I23: =IFERROR(HistoricalFS!I47,0) -> 0.34137106 | J23: =IFERROR(HistoricalFS!J47,0) -> 0.34632439 | ... L23: =IFERROR(HistoricalFS!L47,0) -> 0.29191038 | N23: =IFERROR(AVERAGE(C23:L23),0) -> 0.41883981 | O23: =IFERROR(MEDIAN(C23:L23),0) -> 0.40791092
B24: Return on Equity % | C24: =IFERROR(HistoricalFS!C36/SUM(HistoricalFS!C50:C51),0) -> 0.23846941 | D24: =IFERROR(HistoricalFS!D36/SUM(HistoricalFS!D50:D51),0) -> 0.22072255 | E24: =IFERROR(HistoricalFS!E36/SUM(HistoricalFS!E50:E51),0) -> 0.20940093 | F24: =IFERROR(HistoricalFS!F36/SUM(HistoricalFS!F50:F51),0) -> 0.20424051 | G24: =IFERROR(HistoricalFS!G36/SUM(HistoricalFS!G50:G51),0) -> 0.2388057 | H24: =IFERROR(HistoricalFS!H36/SUM(HistoricalFS!H50:H51),0) -> 0.22450686 | I24: =IFERROR(HistoricalFS!I36/SUM(HistoricalFS!I50:I51),0) -> 0.20192723 | J24: =IFERROR(HistoricalFS!J36/SUM(HistoricalFS!J50:J51),0) -> 0.23535617 | ... L24: =IFERROR(HistoricalFS!L36/SUM(HistoricalFS!L50:L51),0) -> 0.17317128 | N24: =IFERROR(AVERAGE(C24:L24),0) -> 0.2199519 | O24: =IFERROR(MEDIAN(C24:L24),0) -> 0.22261471
B25: Self Sustained Growth Rate | C25: =IFERROR(C23*C24,0) -> 0.1282135 | D25: =IFERROR(D23*D24,0) -> 0.090791687 | E25: =IFERROR(E23*E24,0) -> 0.11017654 | F25: =IFERROR(F23*F24,0) -> 0.097893998 | G25: =IFERROR(G23*G24,0) -> 0.12518065 | H25: =IFERROR(H23*H24,0) -> 0.090809282 | I25: =IFERROR(I23*I24,0) -> 0.068932112 | J25: =IFERROR(J23*J24,0) -> 0.081509583 | ... L25: =IFERROR(L23*L24,0) -> 0.050550495 | N25: =IFERROR(AVERAGE(C25:L25),0) -> 0.092642463 | O25: =IFERROR(MEDIAN(C25:L25),0) -> 0.090800484
B26: Interest Coverage Ratio | C26: =IFERROR(HistoricalFS!C27/HistoricalFS!C21,0) -> 49.98898 | D26: =IFERROR(HistoricalFS!D27/HistoricalFS!D21,0) -> 71.22877 | E26: =IFERROR(HistoricalFS!E27/HistoricalFS!E21,0) -> 68.568604 | F26: =IFERROR(HistoricalFS!F27/HistoricalFS!F21,0) -> 28.449353 | G26: =IFERROR(HistoricalFS!G27/HistoricalFS!G21,0) -> 32.99443 | H26: =IFERROR(HistoricalFS!H27/HistoricalFS!H21,0) -> 44.355888 | I26: =IFERROR(HistoricalFS!I27/HistoricalFS!I21,0) -> 41.790693 | J26: =IFERROR(HistoricalFS!J27/HistoricalFS!J21,0) -> 37.395777 | ... L26: =IFERROR(HistoricalFS!L27/HistoricalFS!L21,0) -> 21.935821 | N26: =IFERROR(AVERAGE(C26:L26),0) -> 42.952003 | O26: =IFERROR(MEDIAN(C26:L26),0) -> 39.593235
B28: Debtor Turnover Ratio | C28: =IFERROR(HistoricalFS!C6/HistoricalFS!C62,0) -> 12.02478 | D28: =IFERROR(HistoricalFS!D6/HistoricalFS!D62,0) -> 10.411994 | E28: =IFERROR(HistoricalFS!E6/HistoricalFS!E62,0) -> 9.7216332 | F28: =IFERROR(HistoricalFS!F6/HistoricalFS!F62,0) -> 10.087468 | G28: =IFERROR(HistoricalFS!G6/HistoricalFS!G62,0) -> 11.258369 | H28: =IFERROR(HistoricalFS!H6/HistoricalFS!H62,0) -> 8.344109 | I28: =IFERROR(HistoricalFS!I6/HistoricalFS!I62,0) -> 7.5169136 | J28: =IFERROR(HistoricalFS!J6/HistoricalFS!J62,0) -> 7.4377909 | ... L28: =IFERROR(HistoricalFS!L6/HistoricalFS!L62,0) -> 7.8600767 | N28: =IFERROR(AVERAGE(C28:L28),0) -> 9.1923181 | O28: =IFERROR(MEDIAN(C28:L28),0) -> 9.0328711
B29: Creditor Turnover Ratio | C29: =IFERROR(HistoricalFS!C9/HistoricalFS!C53,0) -> 2.5367941 | D29: =IFERROR(HistoricalFS!D9/HistoricalFS!D53,0) -> 2.2949191 | E29: =IFERROR(HistoricalFS!E9/HistoricalFS!E53,0) -> 2.3225286 | F29: =IFERROR(HistoricalFS!F9/HistoricalFS!F53,0) -> 2.3642687 | G29: =IFERROR(HistoricalFS!G9/HistoricalFS!G53,0) -> 2.6911814 | H29: =IFERROR(HistoricalFS!H9/HistoricalFS!H53,0) -> 2.1739811 | I29: =IFERROR(HistoricalFS!I9/HistoricalFS!I53,0) -> 2.723624 | J29: =IFERROR(HistoricalFS!J9/HistoricalFS!J53,0) -> 3.0258782 | ... L29: =IFERROR(HistoricalFS!L9/HistoricalFS!L53,0) -> 2.624452 | N29: =IFERROR(AVERAGE(C29:L29),0) -> 2.5403034 | O29: =IFERROR(MEDIAN(C29:L29),0) -> 2.580623
B30: Inventory Turnover | C30: =IFERROR(HistoricalFS!C9/HistoricalFS!C63,0) -> 4.7110657 | D30: =IFERROR(HistoricalFS!D9/HistoricalFS!D63,0) -> 3.7049419 | E30: =IFERROR(HistoricalFS!E9/HistoricalFS!E63,0) -> 4.21101 | F30: =IFERROR(HistoricalFS!F9/HistoricalFS!F63,0) -> 4.0972646 | G30: =IFERROR(HistoricalFS!G9/HistoricalFS!G63,0) -> 3.8816394 | H30: =IFERROR(HistoricalFS!H9/HistoricalFS!H63,0) -> 3.6948007 | I30: =IFERROR(HistoricalFS!I9/HistoricalFS!I63,0) -> 3.3464386 | J30: =IFERROR(HistoricalFS!J9/HistoricalFS!J63,0) -> 3.8267715 | ... L30: =IFERROR(HistoricalFS!L9/HistoricalFS!L63,0) -> 3.3844852 | N30: =IFERROR(AVERAGE(C30:L30),0) -> 3.8743003 | O30: =IFERROR(MEDIAN(C30:L30),0) -> 3.8542054
B31: Fixed Asset Turnover | C31: =IFERROR(HistoricalFS!C6/HistoricalFS!C56,0) -> 4.1774086 | D31: =IFERROR(HistoricalFS!D6/HistoricalFS!D56,0) -> 4.5590724 | E31: =IFERROR(HistoricalFS!E6/HistoricalFS!E56,0) -> 4.5078961 | F31: =IFERROR(HistoricalFS!F6/HistoricalFS!F56,0) -> 2.9615874 | G31: =IFERROR(HistoricalFS!G6/HistoricalFS!G56,0) -> 3.2222977 | H31: =IFERROR(HistoricalFS!H6/HistoricalFS!H56,0) -> 3.7061903 | I31: =IFERROR(HistoricalFS!I6/HistoricalFS!I56,0) -> 5.2728689 | J31: =IFERROR(HistoricalFS!J6/HistoricalFS!J56,0) -> 5.9767488 | ... L31: =IFERROR(HistoricalFS!L6/HistoricalFS!L56,0) -> 3.6773592 | N31: =IFERROR(AVERAGE(C31:L31),0) -> 4.3028075 | O31: =IFERROR(MEDIAN(C31:L31),0) -> 4.3426524
B32: Capital Turnover Ratio | C32: =IFERROR(HistoricalFS!C6/SUM(HistoricalFS!C50:C51),0) -> 2.1872619 | D32: =IFERROR(HistoricalFS!D6/SUM(HistoricalFS!D50:D51),0) -> 1.9808269 | E32: =IFERROR(HistoricalFS!E6/SUM(HistoricalFS!E50:E51),0) -> 2.0004863 | F32: =IFERROR(HistoricalFS!F6/SUM(HistoricalFS!F50:F51),0) -> 2.0315747 | G32: =IFERROR(HistoricalFS!G6/SUM(HistoricalFS!G50:G51),0) -> 1.995156 | H32: =IFERROR(HistoricalFS!H6/SUM(HistoricalFS!H50:H51),0) -> 1.6954785 | I32: =IFERROR(HistoricalFS!I6/SUM(HistoricalFS!I50:I51),0) -> 2.1070234 | J32: =IFERROR(HistoricalFS!J6/SUM(HistoricalFS!J50:J51),0) -> 2.1565842 | ... L32: =IFERROR(HistoricalFS!L6/SUM(HistoricalFS!L50:L51),0) -> 1.7477295 | N32: =IFERROR(AVERAGE(C32:L32),0) -> 1.9797367 | O32: =IFERROR(MEDIAN(C32:L32),0) -> 1.9978212
B34: Debtor Days | C34: =IFERROR(365/C28,0) -> 30.353985 | D34: =IFERROR(365/D28,0) -> 35.055726 | E34: =IFERROR(365/E28,0) -> 37.545132 | F34: =IFERROR(365/F28,0) -> 36.183511 | G34: =IFERROR(365/G28,0) -> 32.420325 | H34: =IFERROR(365/H28,0) -> 43.743436 | I34: =IFERROR(365/I28,0) -> 48.557163 | J34: =IFERROR(365/J28,0) -> 49.073711 | ... L34: =IFERROR(365/L28,0) -> 46.437206 | N34: =IFERROR(AVERAGE(C34:L34),0) -> 40.964536 | O34: =IFERROR(MEDIAN(C34:L34),0) -> 40.644284
B35: Payable Days | C35: =IFERROR(365/C29,0) -> 143.88239 | D35: =IFERROR(365/D29,0) -> 159.047 | E35: =IFERROR(365/E29,0) -> 157.1563 | F35: =IFERROR(365/F29,0) -> 154.38177 | G35: =IFERROR(365/G29,0) -> 135.62817 | H35: =IFERROR(365/H29,0) -> 167.89474 | I35: =IFERROR(365/I29,0) -> 134.01263 | J35: =IFERROR(365/J29,0) -> 120.62614 | ... L35: =IFERROR(365/L29,0) -> 139.07665 | N35: =IFERROR(AVERAGE(C35:L35),0) -> 144.96808 | O35: =IFERROR(MEDIAN(C35:L35),0) -> 141.47952
B36: Inventory Days | C36: =IFERROR(365/C30,0) -> 77.477161 | D36: =IFERROR(365/D30,0) -> 98.517065 | E36: =IFERROR(365/E30,0) -> 86.677543 | F36: =IFERROR(365/F30,0) -> 89.083823 | G36: =IFERROR(365/G30,0) -> 94.032434 | H36: =IFERROR(365/H30,0) -> 98.787466 | I36: =IFERROR(365/I30,0) -> 109.07118 | J36: =IFERROR(365/J30,0) -> 95.380663 | ... L36: =IFERROR(365/L30,0) -> 107.84506 | N36: =IFERROR(AVERAGE(C36:L36),0) -> 95.083352 | O36: =IFERROR(MEDIAN(C36:L36),0) -> 94.706549
B37: Cash Conversion Cycle (in days) | C37: =IFERROR(SUM(C34,C36)-C35,0) -> -36.051243 | D37: =IFERROR(SUM(D34,D36)-D35,0) -> -25.474211 | E37: =IFERROR(SUM(E34,E36)-E35,0) -> -32.933622 | F37: =IFERROR(SUM(F34,F36)-F35,0) -> -29.11444 | G37: =IFERROR(SUM(G34,G36)-G35,0) -> -9.1754087 | H37: =IFERROR(SUM(H34,H36)-H35,0) -> -25.363839 | I37: =IFERROR(SUM(I34,I36)-I35,0) -> 23.615714 | J37: =IFERROR(SUM(J34,J36)-J35,0) -> 23.828237 | ... L37: =IFERROR(SUM(L34,L36)-L35,0) -> 15.205608 | N37: =IFERROR(AVERAGE(C37:L37),0) -> -8.9201892 | O37: =IFERROR(MEDIAN(C37:L37),0) -> -17.269624
B39: CFO/Sales | C39: =IFERROR(HistoricalFS!C73/HistoricalFS!C6,0) -> 0.15716299 | D39: =IFERROR(HistoricalFS!D73/HistoricalFS!D6,0) -> 0.10140294 | E39: =IFERROR(HistoricalFS!E73/HistoricalFS!E6,0) -> 0.12561644 | F39: =IFERROR(HistoricalFS!F73/HistoricalFS!F6,0) -> 0.1283536 | G39: =IFERROR(HistoricalFS!G73/HistoricalFS!G6,0) -> 0.15031975 | H39: =IFERROR(HistoricalFS!H73/HistoricalFS!H6,0) -> 0.16963965 | I39: =IFERROR(HistoricalFS!I73/HistoricalFS!I6,0) -> 0.033898509 | J39: =IFERROR(HistoricalFS!J73/HistoricalFS!J6,0) -> 0.12158891 | ... L39: =IFERROR(HistoricalFS!L73/HistoricalFS!L6,0) -> 0.13047866 | N39: =IFERROR(AVERAGE(C39:L39),0) -> 0.12904194 | O39: =IFERROR(MEDIAN(C39:L39),0) -> 0.12941613
B40: CFO/Total Assets | C40: =IFERROR(HistoricalFS!C73/HistoricalFS!C67,0) -> 0.21242008 | D40: =IFERROR(HistoricalFS!D73/HistoricalFS!D67,0) -> 0.12312024 | E40: =IFERROR(HistoricalFS!E73/HistoricalFS!E67,0) -> 0.15355419 | F40: =IFERROR(HistoricalFS!F73/HistoricalFS!F67,0) -> 0.15198254 | G40: =IFERROR(HistoricalFS!G73/HistoricalFS!G67,0) -> 0.18826098 | H40: =IFERROR(HistoricalFS!H73/HistoricalFS!H67,0) -> 0.18095252 | I40: =IFERROR(HistoricalFS!I73/HistoricalFS!I67,0) -> 0.042968531 | J40: =IFERROR(HistoricalFS!J73/HistoricalFS!J67,0) -> 0.16266637 | ... L40: =IFERROR(HistoricalFS!L73/HistoricalFS!L67,0) -> 0.14573953 | N40: =IFERROR(AVERAGE(C40:L40),0) -> 0.15657935 | O40: =IFERROR(MEDIAN(C40:L40),0) -> 0.15811028
B41: CFO/Total Debt | C41: =IFERROR(HistoricalFS!C73/HistoricalFS!C52,0) -> 6.9378886 | D41: =IFERROR(HistoricalFS!D73/HistoricalFS!D52,0) -> 2.7257201 | E41: =IFERROR(HistoricalFS!E73/HistoricalFS!E52,0) -> 3.9619819 | F41: =IFERROR(HistoricalFS!F73/HistoricalFS!F52,0) -> 1.8714307 | G41: =IFERROR(HistoricalFS!G73/HistoricalFS!G52,0) -> 2.7162718 | H41: =IFERROR(HistoricalFS!H73/HistoricalFS!H52,0) -> 3.3695752 | I41: =IFERROR(HistoricalFS!I73/HistoricalFS!I52,0) -> 0.62165381 | J41: =IFERROR(HistoricalFS!J73/HistoricalFS!J52,0) -> 2.1698161 | ... L41: =IFERROR(HistoricalFS!L73/HistoricalFS!L52,0) -> 1.9316156 | N41: =IFERROR(AVERAGE(C41:L41),0) -> 2.8772673 | O41: =IFERROR(MEDIAN(C41:L41),0) -> 2.5914954

Sheet Common Size Statement
A2: # | B2: ="Common Size Income Statement - "&'[1]Data Sheet'!$B$1 -> Common Size Income Statement - ASIAN PAINTS LTD
B3: Particulars | C3: ='[1]Data Sheet'!B$16 -> 42460 | D3: ='[1]Data Sheet'!C$16 -> 42825 | E3: ='[1]Data Sheet'!D$16 -> 43190 | F3: ='[1]Data Sheet'!E$16 -> 43555 | G3: ='[1]Data Sheet'!F$16 -> 43921 | H3: ='[1]Data Sheet'!G$16 -> 44286 | I3: ='[1]Data Sheet'!H$16 -> 44651 | J3: ='[1]Data Sheet'!I$16 -> 45016 | ... L3: ='[1]Data Sheet'!K$16 -> 45747
B5: ='[1]Data Sheet'!A17 -> Sales | C5: ='Data Sheet'!B17/'Data Sheet'!B$17 -> 1 | D5: ='Data Sheet'!C17/'Data Sheet'!C$17 -> 1 | E5: ='Data Sheet'!D17/'Data Sheet'!D$17 -> 1 | F5: ='Data Sheet'!E17/'Data Sheet'!E$17 -> 1 | G5: ='Data Sheet'!F17/'Data Sheet'!F$17 -> 1 | H5: ='Data Sheet'!G17/'Data Sheet'!G$17 -> 1 | I5: ='Data Sheet'!H17/'Data Sheet'!H$17 -> 1 | J5: ='Data Sheet'!I17/'Data Sheet'!I$17 -> 1 | ... L5: ='Data Sheet'!K17/'Data Sheet'!K$17 -> 1
B6: ='[1]Data Sheet'!A18 -> Raw Material Cost | C6: ='Data Sheet'!B18/'Data Sheet'!B$17 -> 0.46034647 | D6: ='Data Sheet'!C18/'Data Sheet'!C$17 -> 0.49479518 | E6: ='Data Sheet'!D18/'Data Sheet'!D$17 -> 0.48311366 | F6: ='Data Sheet'!E18/'Data Sheet'!E$17 -> 0.51841646 | G6: ='Data Sheet'!F18/'Data Sheet'!F$17 -> 0.49388286 | H6: ='Data Sheet'!G18/'Data Sheet'!G$17 -> 0.48015709 | I6: ='Data Sheet'!H18/'Data Sheet'!H$17 -> 0.58840195 | J6: ='Data Sheet'!I18/'Data Sheet'!I$17 -> 0.55048728 | ... L6: ='Data Sheet'!K18/'Data Sheet'!K$17 -> 0.51627164
B7: ='[1]Data Sheet'!A19 -> Change in Inventory | C7: ='Data Sheet'!B19/'Data Sheet'!B$17 -> -0.013967007 | D7: ='Data Sheet'!C19/'Data Sheet'!C$17 -> 0.035094964 | E7: ='Data Sheet'!D19/'Data Sheet'!D$17 -> -0.0084477742 | F7: ='Data Sheet'!E19/'Data Sheet'!E$17 -> 0.015242101 | G7: ='Data Sheet'!F19/'Data Sheet'!F$17 -> 0.011832519 | H7: ='Data Sheet'!G19/'Data Sheet'!G$17 -> 0.0042578591 | I7: ='Data Sheet'!H19/'Data Sheet'!H$17 -> 0.045529612 | J7: ='Data Sheet'!I19/'Data Sheet'!I$17 -> 0.0089806513 | ... L7: ='Data Sheet'!K19/'Data Sheet'!K$17 -> 0.0060461953
B8: ='[1]Data Sheet'!A20 -> Power and Fuel | C8: ='Data Sheet'!B20/'Data Sheet'!B$17 -> 0.0080215871 | D8: ='Data Sheet'!C20/'Data Sheet'!C$17 -> 0.0070389105 | E8: ='Data Sheet'!D20/'Data Sheet'!D$17 -> 0.006555896 | F8: ='Data Sheet'!E20/'Data Sheet'!E$17 -> 0.0062177335 | G8: ='Data Sheet'!F20/'Data Sheet'!F$17 -> 0.0048383945 | H8: ='Data Sheet'!G20/'Data Sheet'!G$17 -> 0.0039631019 | I8: ='Data Sheet'!H20/'Data Sheet'!H$17 -> 0.0040283451 | J8: ='Data Sheet'!I20/'Data Sheet'!I$17 -> 0.0040097319 | ... L8: ='Data Sheet'!K20/'Data Sheet'!K$17 -> 0.0043821644
B9: ='[1]Data Sheet'!A21 -> Other Mfr. Exp | C9: ='Data Sheet'!B21/'Data Sheet'!B$17 -> 0.10757251 | D9: ='Data Sheet'!C21/'Data Sheet'!C$17 -> 0.11039378 | E9: ='Data Sheet'!D21/'Data Sheet'!D$17 -> 0.10054831 | F9: ='Data Sheet'!E21/'Data Sheet'!E$17 -> 0.096795084 | G9: ='Data Sheet'!F21/'Data Sheet'!F$17 -> 0.096288948 | H9: ='Data Sheet'!G21/'Data Sheet'!G$17 -> 0.09525768 | I9: ='Data Sheet'!H21/'Data Sheet'!H$17 -> 0.098980182 | J9: ='Data Sheet'!I21/'Data Sheet'!I$17 -> 0.084555501 | ... L9: ='Data Sheet'!K21/'Data Sheet'!K$17 -> 0.079261196
B10: ='[1]Data Sheet'!A22 -> Employee Cost | C10: ='Data Sheet'!B22/'Data Sheet'!B$17 -> 0.069718018 | D10: ='Data Sheet'!C22/'Data Sheet'!C$17 -> 0.069040678 | E10: ='Data Sheet'!D22/'Data Sheet'!D$17 -> 0.066681724 | F10: ='Data Sheet'!E22/'Data Sheet'!E$17 -> 0.064588441 | G10: ='Data Sheet'!F22/'Data Sheet'!F$17 -> 0.067846867 | H10: ='Data Sheet'!G22/'Data Sheet'!G$17 -> 0.071276423 | I10: ='Data Sheet'!H22/'Data Sheet'!H$17 -> 0.061667734 | J10: ='Data Sheet'!I22/'Data Sheet'!I$17 -> 0.059045905 | ... L10: ='Data Sheet'!K22/'Data Sheet'!K$17 -> 0.076853926
B11: ='[1]Data Sheet'!A23 -> Selling and admin | C11: ='Data Sheet'!B23/'Data Sheet'!B$17 -> 0.27413396 | D11: ='Data Sheet'!C23/'Data Sheet'!C$17 -> 0.28973861 | E11: ='Data Sheet'!D23/'Data Sheet'!D$17 -> 0.13402558 | F11: ='Data Sheet'!E23/'Data Sheet'!E$17 -> 0.12301736 | G11: ='Data Sheet'!F23/'Data Sheet'!F$17 -> 0.11436749 | H11: ='Data Sheet'!G23/'Data Sheet'!G$17 -> 0.10342706 | I11: ='Data Sheet'!H23/'Data Sheet'!H$17 -> 0.10109452 | J11: ='Data Sheet'!I23/'Data Sheet'!I$17 -> 0.10150719 | ... L11: ='Data Sheet'!K23/'Data Sheet'!K$17 -> 0.11428607
B12: ='[1]Data Sheet'!A24 -> Other Expenses | C12: ='Data Sheet'!B24/'Data Sheet'!B$17 -> -0.12470247 | D12: ='Data Sheet'!C24/'Data Sheet'!C$17 -> -0.13467477 | E12: ='Data Sheet'!D24/'Data Sheet'!D$17 -> 0.010190466 | F12: ='Data Sheet'!E24/'Data Sheet'!E$17 -> 0.010525397 | G12: ='Data Sheet'!F24/'Data Sheet'!F$17 -> 0.028939328 | H12: ='Data Sheet'!G24/'Data Sheet'!G$17 -> 0.026547947 | I12: ='Data Sheet'!H24/'Data Sheet'!H$17 -> 0.026291627 | J12: ='Data Sheet'!I24/'Data Sheet'!I$17 -> 0.027870377 | ... L12: ='Data Sheet'!K24/'Data Sheet'!K$17 -> 0.037846233
B13: ='[1]Data Sheet'!A25 -> Other Income | C13: ='Data Sheet'!B25/'Data Sheet'!B$17 -> 0.014952188 | D13: ='Data Sheet'!C25/'Data Sheet'!C$17 -> 0.022433955 | E13: ='Data Sheet'!D25/'Data Sheet'!D$17 -> 0.019995186 | F13: ='Data Sheet'!E25/'Data Sheet'!E$17 -> 0.014229114 | G13: ='Data Sheet'!F25/'Data Sheet'!F$17 -> 0.017566949 | H13: ='Data Sheet'!G25/'Data Sheet'!G$17 -> 0.015274407 | I13: ='Data Sheet'!H25/'Data Sheet'!H$17 -> 0.01016725 | J13: ='Data Sheet'!I25/'Data Sheet'!I$17 -> 0.012510224 | ... L13: ='Data Sheet'!K25/'Data Sheet'!K$17 -> 0.010329261
B14: ='[1]Data Sheet'!A26 -> Depreciation | C14: ='Data Sheet'!B26/'Data Sheet'!B$17 -> 0.019309827 | D14: ='Data Sheet'!C26/'Data Sheet'!C$17 -> 0.022227475 | E14: ='Data Sheet'!D26/'Data Sheet'!D$17 -> 0.021425239 | F14: ='Data Sheet'!E26/'Data Sheet'!E$17 -> 0.03233554 | G14: ='Data Sheet'!F26/'Data Sheet'!F$17 -> 0.038617107 | H14: ='Data Sheet'!G26/'Data Sheet'!G$17 -> 0.036442576 | I14: ='Data Sheet'!H26/'Data Sheet'!H$17 -> 0.028052374 | J14: ='Data Sheet'!I26/'Data Sheet'!I$17 -> 0.024878373 | ... L14: ='Data Sheet'!K26/'Data Sheet'!K$17 -> 0.030270498
B15: ='[1]Data Sheet'!A27 -> Interest | C15: ='Data Sheet'!B27/'Data Sheet'!B$17 -> 0.0034334187 | D15: ='Data Sheet'!C27/'Data Sheet'!C$17 -> 0.0024784242 | E15: ='Data Sheet'!D27/'Data Sheet'!D$17 -> 0.0024648505 | F15: ='Data Sheet'!E27/'Data Sheet'!E$17 -> 0.0057416452 | G15: ='Data Sheet'!F27/'Data Sheet'!F$17 -> 0.0050630218 | H15: ='Data Sheet'!G27/'Data Sheet'!G$17 -> 0.0042200933 | I15: ='Data Sheet'!H27/'Data Sheet'!H$17 -> 0.0032785499 | J15: ='Data Sheet'!I27/'Data Sheet'!I$17 -> 0.0041883417 | ... L15: ='Data Sheet'!K27/'Data Sheet'!K$17 -> 0.0066956451
B16: ='[1]Data Sheet'!A28 -> Profit before tax | C16: ='Data Sheet'!B28/'Data Sheet'!B$17 -> 0.18315186 | D16: ='Data Sheet'!C28/'Data Sheet'!C$17 -> 0.19649064 | E16: ='Data Sheet'!D28/'Data Sheet'!D$17 -> 0.18654169 | F16: ='Data Sheet'!E28/'Data Sheet'!E$17 -> 0.17183356 | G16: ='Data Sheet'!F28/'Data Sheet'!F$17 -> 0.17955545 | H16: ='Data Sheet'!G28/'Data Sheet'!G$17 -> 0.1982403 | I16: ='Data Sheet'!H28/'Data Sheet'!H$17 -> 0.14390157 | J16: ='Data Sheet'!I28/'Data Sheet'!I$17 -> 0.16494818 | ... L16: ='Data Sheet'!K28/'Data Sheet'!K$17 -> 0.15050809
... B19: ='[1]Data Sheet'!A31 -> Dividend Amount | C19: ='Data Sheet'!B31/'Data Sheet'!B$17 -> 0.050408191 | D19: ='Data Sheet'!C31/'Data Sheet'!C$17 -> 0.065594254 | E19: ='Data Sheet'!D31/'Data Sheet'!D$17 -> 0.049600138 | F19: ='Data Sheet'!E31/'Data Sheet'!E$17 -> 0.05234684 | G19: ='Data Sheet'!F31/'Data Sheet'!F$17 -> 0.056950461 | H19: ='Data Sheet'!G31/'Data Sheet'!G$17 -> 0.078855366 | I19: ='Data Sheet'!H31/'Data Sheet'!H$17 -> 0.063119904 | J19: ='Data Sheet'!I31/'Data Sheet'!I$17 -> 0.071338086 | ... L19: ='Data Sheet'!K31/'Data Sheet'!K$17 -> 0.07016005
B20: EBITDA | C20: =HistoricalFS!C12/'Data Sheet'!B17 -> 0.34037441 | D20: =HistoricalFS!D12/'Data Sheet'!C17 -> 0.35382642 | E20: =HistoricalFS!E12/'Data Sheet'!D17 -> 0.33465264 | F20: =HistoricalFS!F12/'Data Sheet'!E17 -> 0.32922439 | G20: =HistoricalFS!G12/'Data Sheet'!F17 -> 0.34897545 | H20: =HistoricalFS!H12/'Data Sheet'!G17 -> 0.35360357 | I20: =HistoricalFS!I12/'Data Sheet'!H17 -> 0.2924514 | J20: =HistoricalFS!J12/'Data Sheet'!I17 -> 0.31088224 | ... L20: =HistoricalFS!L12/'Data Sheet'!K17 -> 0.32927727
A23: # | B23: ="Common Size Balance Sheet - "&'[1]Data Sheet'!$B$1 -> Common Size Balance Sheet - ASIAN PAINTS LTD
B24: Particulars | C24: ='[1]Data Sheet'!B$16 -> 42460 | D24: ='[1]Data Sheet'!C$16 -> 42825 | E24: ='[1]Data Sheet'!D$16 -> 43190 | F24: ='[1]Data Sheet'!E$16 -> 43555 | G24: ='[1]Data Sheet'!F$16 -> 43921 | H24: ='[1]Data Sheet'!G$16 -> 44286 | I24: ='[1]Data Sheet'!H$16 -> 44651 | J24: ='[1]Data Sheet'!I$16 -> 45016 | ... L24: ='[1]Data Sheet'!K$16 -> 45747
B26: Total Liabilities | C26: ='Data Sheet'!B61/'Data Sheet'!B$61 -> 1 | D26: ='Data Sheet'!C61/'Data Sheet'!C$61 -> 1 | E26: ='Data Sheet'!D61/'Data Sheet'!D$61 -> 1 | F26: ='Data Sheet'!E61/'Data Sheet'!E$61 -> 1 | G26: ='Data Sheet'!F61/'Data Sheet'!F$61 -> 1 | H26: ='Data Sheet'!G61/'Data Sheet'!G$61 -> 1 | I26: ='Data Sheet'!H61/'Data Sheet'!H$61 -> 1 | J26: ='Data Sheet'!I61/'Data Sheet'!I$61 -> 1 | ... L26: ='Data Sheet'!K61/'Data Sheet'!K$61 -> 1
B27: ='[1]Data Sheet'!A57 -> Equity Share Capital | C27: ='Data Sheet'!B57/'Data Sheet'!B$61 -> 0.0090841678 | D27: ='Data Sheet'!C57/'Data Sheet'!C$61 -> 0.0077322476 | E27: ='Data Sheet'!D57/'Data Sheet'!D$61 -> 0.0069691677 | F27: ='Data Sheet'!E57/'Data Sheet'!E$61 -> 0.0059031906 | G27: ='Data Sheet'!F57/'Data Sheet'!F$61 -> 0.0059437463 | H27: ='Data Sheet'!G57/'Data Sheet'!G$61 -> 0.004712277 | I27: ='Data Sheet'!H57/'Data Sheet'!H$61 -> 0.004177986 | J27: ='Data Sheet'!I57/'Data Sheet'!I$61 -> 0.0037208104 | ... L27: ='Data Sheet'!K57/'Data Sheet'!K$61 -> 0.0031599147
B28: ='[1]Data Sheet'!A58 -> Reserves | C28: ='Data Sheet'!B58/'Data Sheet'!B$61 -> 0.60885328 | D28: ='Data Sheet'!C58/'Data Sheet'!C$61 -> 0.60522813 | E28: ='Data Sheet'!D58/'Data Sheet'!D$61 -> 0.60408487 | F28: ='Data Sheet'!E58/'Data Sheet'!E$61 -> 0.57694149 | G28: ='Data Sheet'!F58/'Data Sheet'!F$61 -> 0.62177833 | H28: ='Data Sheet'!G58/'Data Sheet'!G$61 -> 0.62442435 | I28: ='Data Sheet'!H58/'Data Sheet'!H$61 -> 0.59741193 | J28: ='Data Sheet'!I58/'Data Sheet'!I$61 -> 0.61663007 | ... L28: ='Data Sheet'!K58/'Data Sheet'!K$61 -> 0.6359325
B29: ='[1]Data Sheet'!A59 -> Borrowings | C29: ='Data Sheet'!B59/'Data Sheet'!B$61 -> 0.030617396 | D29: ='Data Sheet'!C59/'Data Sheet'!C$61 -> 0.045169804 | E29: ='Data Sheet'!D59/'Data Sheet'!D$61 -> 0.038756913 | F29: ='Data Sheet'!E59/'Data Sheet'!E$61 -> 0.081211951 | G29: ='Data Sheet'!F59/'Data Sheet'!F$61 -> 0.069308593 | H29: ='Data Sheet'!G59/'Data Sheet'!G$61 -> 0.053701879 | I29: ='Data Sheet'!H59/'Data Sheet'!H$61 -> 0.069119709 | J29: ='Data Sheet'!I59/'Data Sheet'!I$61 -> 0.074967813 | ... L29: ='Data Sheet'!K59/'Data Sheet'!K$61 -> 0.075449552
B30: ='[1]Data Sheet'!A60 -> Other Liabilities | C30: ='Data Sheet'!B60/'Data Sheet'!B$61 -> 0.35144516 | D30: ='Data Sheet'!C60/'Data Sheet'!C$61 -> 0.34186981 | E30: ='Data Sheet'!D60/'Data Sheet'!D$61 -> 0.35018905 | F30: ='Data Sheet'!E60/'Data Sheet'!E$61 -> 0.33594337 | G30: ='Data Sheet'!F60/'Data Sheet'!F$61 -> 0.30296933 | H30: ='Data Sheet'!G60/'Data Sheet'!G$61 -> 0.31716149 | I30: ='Data Sheet'!H60/'Data Sheet'!H$61 -> 0.32929037 | J30: ='Data Sheet'!I60/'Data Sheet'!I$61 -> 0.30468131 | ... L30: ='Data Sheet'!K60/'Data Sheet'!K$61 -> 0.28545803
B32: Total Assets | C32: ='Data Sheet'!B66/'Data Sheet'!B$66 -> 1 | D32: ='Data Sheet'!C66/'Data Sheet'!C$66 -> 1 | E32: ='Data Sheet'!D66/'Data Sheet'!D$66 -> 1 | F32: ='Data Sheet'!E66/'Data Sheet'!E$66 -> 1 | G32: ='Data Sheet'!F66/'Data Sheet'!F$66 -> 1 | H32: ='Data Sheet'!G66/'Data Sheet'!G$66 -> 1 | I32: ='Data Sheet'!H66/'Data Sheet'!H$66 -> 1 | J32: ='Data Sheet'!I66/'Data Sheet'!I$66 -> 1 | ... L32: ='Data Sheet'!K66/'Data Sheet'!K$66 -> 1
B33: ='[1]Data Sheet'!A62 -> Net Block | C33: ='Data Sheet'!B62/'Data Sheet'!B$66 -> 0.32354771 | D33: ='Data Sheet'!C62/'Data Sheet'!C$66 -> 0.26631918 | E33: ='Data Sheet'!D62/'Data Sheet'!D$66 -> 0.27116979 | F33: ='Data Sheet'!E62/'Data Sheet'!E$66 -> 0.39981685 | G33: ='Data Sheet'!F62/'Data Sheet'!F$66 -> 0.38866784 | H33: ='Data Sheet'!G62/'Data Sheet'!G$66 -> 0.28781244 | I33: ='Data Sheet'!H62/'Data Sheet'!H$66 -> 0.24039362 | J33: ='Data Sheet'!I62/'Data Sheet'!I$66 -> 0.22384057 | ... L33: ='Data Sheet'!K62/'Data Sheet'!K$66 -> 0.30373988
B34: ='[1]Data Sheet'!A63 -> Capital Work in Progress | C34: ='Data Sheet'!B63/'Data Sheet'!B$66 -> 0.010094677 | D34: ='Data Sheet'!C63/'Data Sheet'!C$66 -> 0.020760665 | E34: ='Data Sheet'!D63/'Data Sheet'!D$66 -> 0.10208973 | F34: ='Data Sheet'!E63/'Data Sheet'!E$66 -> 0.01290369 | G34: ='Data Sheet'!F63/'Data Sheet'!F$66 -> 0.0086900645 | H34: ='Data Sheet'!G63/'Data Sheet'!G$66 -> 0.0089892873 | I34: ='Data Sheet'!H63/'Data Sheet'!H$66 -> 0.018574005 | J34: ='Data Sheet'!I63/'Data Sheet'!I$66 -> 0.039550679 | ... L34: ='Data Sheet'!K63/'Data Sheet'!K$66 -> 0.041326953
B35: ='[1]Data Sheet'!A64 -> Investments | C35: ='Data Sheet'!B64/'Data Sheet'!B$66 -> 0.25685409 | D35: ='Data Sheet'!C64/'Data Sheet'!C$66 -> 0.21378068 | E35: ='Data Sheet'!D64/'Data Sheet'!D$66 -> 0.15553479 | F35: ='Data Sheet'!E64/'Data Sheet'!E$66 -> 0.15807775 | G35: ='Data Sheet'!F64/'Data Sheet'!F$66 -> 0.12509938 | H35: ='Data Sheet'!G64/'Data Sheet'!G$66 -> 0.23270552 | I35: ='Data Sheet'!H64/'Data Sheet'!H$66 -> 0.14145262 | J35: ='Data Sheet'!I64/'Data Sheet'!I$66 -> 0.165315 | ... L35: ='Data Sheet'!K64/'Data Sheet'!K$66 -> 0.15564853
B36: ='[1]Data Sheet'!A65 -> Other Assets | C36: =HistoricalFS!C59/'Data Sheet'!B$66 -> 0.067684248 | D36: =HistoricalFS!D59/'Data Sheet'!C$66 -> 0.10617895 | E36: =HistoricalFS!E59/'Data Sheet'!D$66 -> 0.1229224 | F36: =HistoricalFS!F59/'Data Sheet'!E$66 -> 0.09058862 | G36: =HistoricalFS!G59/'Data Sheet'!F$66 -> 0.10774032 | H36: =HistoricalFS!H59/'Data Sheet'!G$66 -> 0.12603671 | I36: =HistoricalFS!I59/'Data Sheet'!H$66 -> 0.12529864 | J36: =HistoricalFS!J59/'Data Sheet'!I$66 -> 0.11777536 | ... L36: =HistoricalFS!L59/'Data Sheet'!K$66 -> 0.11006366
B37: ='[1]Data Sheet'!A67 -> Receivables | C37: ='Data Sheet'!B67/'Data Sheet'!B$66 -> 0.11240048 | D37: ='Data Sheet'!C67/'Data Sheet'!C$66 -> 0.11661248 | E37: ='Data Sheet'!D67/'Data Sheet'!D$66 -> 0.12574073 | F37: ='Data Sheet'!E67/'Data Sheet'!E$66 -> 0.11738253 | G37: ='Data Sheet'!F67/'Data Sheet'!F$66 -> 0.111242 | H37: ='Data Sheet'!G67/'Data Sheet'!G$66 -> 0.12783722 | I37: ='Data Sheet'!H67/'Data Sheet'!H$66 -> 0.16862826 | J37: ='Data Sheet'!I67/'Data Sheet'!I$66 -> 0.17987046 | ... L37: ='Data Sheet'!K67/'Data Sheet'!K$66 -> 0.14210557
B38: ='[1]Data Sheet'!A68 -> Inventory | C38: ='Data Sheet'!B68/'Data Sheet'!B$66 -> 0.18924466 | D38: ='Data Sheet'!C68/'Data Sheet'!C$66 -> 0.21176137 | E38: ='Data Sheet'!D68/'Data Sheet'!D$66 -> 0.19314229 | F38: ='Data Sheet'!E68/'Data Sheet'!E$66 -> 0.19385138 | G38: ='Data Sheet'!F68/'Data Sheet'!F$66 -> 0.21005182 | H38: ='Data Sheet'!G68/'Data Sheet'!G$66 -> 0.18661442 | I38: ='Data Sheet'!H68/'Data Sheet'!H$66 -> 0.26800526 | J38: ='Data Sheet'!I68/'Data Sheet'!I$66 -> 0.24091549 | ... L38: ='Data Sheet'!K68/'Data Sheet'!K$66 -> 0.22135446
B39: ='[1]Data Sheet'!A69 -> Cash & Bank | C39: ='Data Sheet'!B69/'Data Sheet'!B$66 -> 0.040174145 | D39: ='Data Sheet'!C69/'Data Sheet'!C$66 -> 0.064586677 | E39: ='Data Sheet'!D69/'Data Sheet'!D$66 -> 0.029400268 | F39: ='Data Sheet'!E69/'Data Sheet'!E$66 -> 0.027379185 | G39: ='Data Sheet'!F69/'Data Sheet'!F$66 -> 0.048508579 | H39: ='Data Sheet'!G69/'Data Sheet'!G$66 -> 0.030004412 | I39: ='Data Sheet'!H69/'Data Sheet'!H$66 -> 0.037647609 | J39: ='Data Sheet'!I69/'Data Sheet'!I$66 -> 0.032732426 | ... L39: ='Data Sheet'!K69/'Data Sheet'!K$66 -> 0.025760947

Sheet FCF
B7: Unlevered Free Cash Flow Statement (Cr.)
B8: Years | C8: ='Data Sheet'!I16 -> 45016 | D8: ='Data Sheet'!J16 -> 45382 | E8: ='Data Sheet'!K16 -> 45747 | F8: =E8+365 -> 46112 | G8: =F8+365 -> 46477 | H8: =G8+365 -> 46842 | I8: =H8+365 -> 47207 | J8: =I8+365 -> 47572
B10: ='Data Sheet'!A17 -> Sales | C10: =IFERROR('Data Sheet'!I17,0) -> 34488.59 | D10: =IFERROR('Data Sheet'!J17,0) -> 35494.73 | E10: =IFERROR('Data Sheet'!K17,0) -> 33905.62 | F10: =E10*(1+$C$35) -> 36558.832 | G10: =F10*(1+$C$35) -> 39419.666 | H10: =G10*(1+$C$35) -> 42504.368 | I10: =H10*(1+$C$35) -> 45830.456 | J10: =I10*(1+$C$35) -> 49416.821
B11: COGS | C11: =IFERROR(SUM('Data Sheet'!I18,'Data Sheet'!I20:I22)-1*'Data Sheet'!I19,0) -> 23766.7 | D11: =IFERROR(SUM('Data Sheet'!J18,'Data Sheet'!J20:J22)-1*'Data Sheet'!J19,0) -> 23009.99 | E11: =IFERROR(SUM('Data Sheet'!K18,'Data Sheet'!K20:K22)-1*'Data Sheet'!K19,0) -> 22741.27 | F11: =E11*(1+$C$36) -> 24556.213 | G11: =F11*(1+$C$36) -> 26516.004 | H11: =G11*(1+$C$36) -> 28632.203 | I11: =H11*(1+$C$36) -> 30917.292 | J11: =I11*(1+$C$36) -> 33384.75
B13: Gross Profit | C13: =C10-C11 -> 10721.89 | D13: =D10-D11 -> 12484.74 | E13: =E10-E11 -> 11164.35 | F13: =F10-F11 -> 12002.619 | G13: =G10-G11 -> 12903.661 | H13: =H10-H11 -> 13872.165 | I13: =I10-I11 -> 14913.165 | J13: =J10-J11 -> 16032.071
B14: Selling & General Expenses | C14: =IFERROR(SUM('Data Sheet'!I23:I24),0) -> 4462.05 | D14: =IFERROR(SUM('Data Sheet'!J23:J24),0) -> 4899.76 | E14: =IFERROR(SUM('Data Sheet'!K23:K24),0) -> 5158.14 | F14: =E14*(1+$C$37) -> 5438.936 | G14: =F14*(1+$C$37) -> 5735.0178 | H14: =G14*(1+$C$37) -> 6047.2175 | I14: =H14*(1+$C$37) -> 6376.4126 | J14: =I14*(1+$C$37) -> 6723.5282
B16: EBITDA | C16: =C13-C14 -> 6259.84 | D16: =D13-D14 -> 7584.98 | E16: =E13-E14 -> 6006.21 | F16: =F13-F14 -> 6563.6828 | G16: =G13-G14 -> 7168.6437 | H16: =H13-H14 -> 7824.9473 | I16: =I13-I14 -> 8536.7521 | J16: =J13-J14 -> 9308.5431
B17: ='Data Sheet'!A27 -> Interest | C17: =IFERROR('Data Sheet'!I27,0) -> 144.45 | D17: =IFERROR('Data Sheet'!J27,0) -> 205.17 | E17: =IFERROR('Data Sheet'!K27,0) -> 227.02 | F17: =E17*(1+$C$38) -> 239.76881 | G17: =F17*(1+$C$38) -> 253.23356 | H17: =G17*(1+$C$38) -> 267.45445 | I17: =H17*(1+$C$38) -> 282.47395 | J17: =I17*(1+$C$38) -> 298.3369
B18: ='Data Sheet'!A26 -> Depreciation | C18: =IFERROR('Data Sheet'!I26,0) -> 858.02 | D18: =IFERROR('Data Sheet'!J26,0) -> 853 | E18: =IFERROR('Data Sheet'!K26,0) -> 1026.34 | F18: =E18*(1+$C$39) -> 1099.4069 | G18: =F18*(1+$C$39) -> 1177.6756 | H18: =G18*(1+$C$39) -> 1261.5164 | I18: =H18*(1+$C$39) -> 1351.3259 | J18: =I18*(1+$C$39) -> 1447.5292
B20: EBIT | C20: =C16-C18 -> 5401.82 | D20: =D16-D18 -> 6731.98 | E20: =E16-E18 -> 4979.87 | F20: =F16-F18 -> 5464.2759 | G20: =G16-G18 -> 5990.9681 | H20: =H16-H18 -> 6563.431 | I20: =I16-I18 -> 7185.4262 | J20: =J16-J18 -> 7861.014
B22: EBT | C22: =C16-SUM(C17:C18) -> 5257.37 | D22: =D16-SUM(D17:D18) -> 6526.81 | E22: =E16-SUM(E17:E18) -> 4752.85 | F22: =F16-SUM(F17:F18) -> 5224.5071 | G22: =G16-SUM(G17:G18) -> 5737.7345 | H22: =H16-SUM(H17:H18) -> 6295.9765 | I22: =I16-SUM(I17:I18) -> 6902.9522 | J22: =J16-SUM(J17:J18) -> 7562.6771
B23: Tax | C23: 0.25 | D23: 0.25 | E23: 0.25 | F23: 0.25 | G23: 0.25 | H23: 0.25 | I23: 0.25 | J23: 0.25
B25: NOPAT | C25: =C20*(1-C23) -> 4051.365 | D25: =D20*(1-D23) -> 5048.985 | E25: =E20*(1-E23) -> 3734.9025 | F25: =F20*(1-F23) -> 4098.2069 | G25: =G20*(1-G23) -> 4493.226 | H25: =H20*(1-H23) -> 4922.5732 | I25: =I20*(1-I23) -> 5389.0696 | J25: =J20*(1-J23) -> 5895.7605
B26: Add: Depriciation and amortisation | C26: =C18 -> 858.02 | D26: =D18 -> 853 | E26: =E18 -> 1026.34 | F26: =F18 -> 1099.4069 | G26: =G18 -> 1177.6756 | H26: =H18 -> 1261.5164 | I26: =I18 -> 1351.3259 | J26: =J18 -> 1447.5292
B27: Less: Capital Expenditure | C27: =IFERROR(-SUM('Raw CF'!L13:L14),0) -> 1420 | D27: =IFERROR(-SUM('Raw CF'!M13:M14),0) -> 2491 | E27: =IFERROR(-SUM('Raw CF'!N13:N14),0) -> 1820 | F27: ='Fixed Assets'!F7 -> 2478.7781 | G27: ='Fixed Assets'!G7 -> 2688.4951 | H27: ='Fixed Assets'!H7 -> 2915.9553 | I27: ='Fixed Assets'!I7 -> 3162.6597 | J27: ='Fixed Assets'!J7 -> 3430.2366
B28: Less: Change in Working Capital | D28: ='Change in WC'!D17 -> -56 | E28: ='Change in WC'!E17 -> 5 | F28: ='Change in WC'!F17 -> 387.58802 | G28: ='Change in WC'!G17 -> 546.32688 | H28: ='Change in WC'!H17 -> 589.40933 | I28: ='Change in WC'!I17 -> 635.88951 | J28: ='Change in WC'!J17 -> 686.0354
B30: Unlevered Free Cash Flow | D30: =D25+D26-D27-D28 -> 3466.985 | E30: =E25+E26-E27-E28 -> 2936.2425 | F30: =F25+F26-F27-F28 -> 2331.2477 | G30: =G25+G26-G27-G28 -> 2436.0796 | H30: =H25+H26-H27-H28 -> 2678.725 | I30: =I25+I26-I27-I28 -> 2941.8463 | J30: =J25+J26-J27-J28 -> 3227.0177
B33: Forecasts %
B35: Sales Growth % | C35: =Forecasts!C21 -> 0.07825287
B36: COGS Growth % | C36: =Forecasts!G21 -> 0.079808351
B37: Selling & General Exp. Growth % | C37: =Forecasts!K21 -> 0.054437449
B38: Interest Growth % | C38: =Forecasts!O21 -> 0.056157217
B39: Depriciation Growth % | C39: =Forecasts!S21 -> 0.071191734

Sheet Forecasts
B2: Sales Forecasting | F2: COGS Forecasting | J2: S&G Expenses Forecasting | N2: Interest Forecasting | R2: Depriciation Forecasting
B3: Fiscal Years | C3: Sales | D3: Growth % | F3: Fiscal Years | G3: COGS | H3: Growth % | J3: Fiscal Years | K3: Expenses | L3: Growth % | N3: Fiscal Years | O3: Interests | P3: Growth % | R3: Fiscal Years | S3: Interests | T3: Growth %
B5: 2016 | C5: {=IFERROR(TRANSPOSE('Data Sheet'!B17:K17),0)} -> 14271.49 | D5: =0 -> 0 | F5: 2016 | G5: {=IFERROR(TRANSPOSE(HistoricalFS!C9:L9),0)} -> 9413.84 | H5: =0 -> 0 | J5: 2016 | K5: {=IFERROR(TRANSPOSE(HistoricalFS!C15:L15),0)} -> 2132.61 | L5: =0 -> 0 | N5: 2016 | O5: {=IFERROR(TRANSPOSE(HistoricalFS!C21:L21),0)} -> 49 | P5: =0 -> 0 | R5: 2016 | S5: {=IFERROR(TRANSPOSE(HistoricalFS!C24:L24),0)} -> 275.58 | T5: =0 -> 0
B6: 2017 | C6: 15061.99 | D6: =C6/C5-1 -> 0.055390152 | F6: 2017 | G6: 9732.66 | H6: =G6/G5-1 -> 0.033867157 | J6: 2017 | K6: 2335.57 | L6: =K6/K5-1 -> 0.095169768 | N6: 2017 | O6: 37.33 | P6: =O6/O5-1 -> -0.23816327 | R6: 2017 | S6: 334.79 | T6: =S6/S5-1 -> 0.21485594
B7: 2018 | C7: 16824.55 | D7: =C7/C6-1 -> 0.11702039 | F7: 2018 | G7: 11194.17 | H7: =G7/G6-1 -> 0.15016553 | J7: 2018 | K7: 2426.37 | L7: =K7/K6-1 -> 0.038877019 | N7: 2018 | O7: 41.47 | P7: =O7/O6-1 -> 0.11090276 | R7: 2018 | S7: 360.47 | T7: =S7/S6-1 -> 0.0767048
B8: 2019 | C8: 19240.13 | D8: =C8/C7-1 -> 0.14357472 | F8: 2019 | G8: 12905.81 | H8: =G8/G7-1 -> 0.15290459 | J8: 2019 | K8: 2569.38 | L8: =K8/K7-1 -> 0.058939898 | N8: 2019 | O8: 110.47 | P8: =O8/O7-1 -> 1.6638534 | R8: 2019 | S8: 622.14 | T8: =S8/S7-1 -> 0.72591339
B9: 2020 | C9: 20211.25 | D9: =C9/C8-1 -> 0.050473671 | F9: 2020 | G9: 13158.02 | H9: =G9/G8-1 -> 0.019542361 | J9: 2020 | K9: 2896.41 | L9: =K9/K8-1 -> 0.12727973 | N9: 2020 | O9: 102.33 | P9: =O9/O8-1 -> -0.073685163 | R9: 2020 | S9: 780.5 | T9: =S9/S8-1 -> 0.25454078
B10: 2021 | C10: 21712.79 | D10: =C10/C9-1 -> 0.074292288 | F10: 2021 | G10: 14035.07 | H10: =G10/G9-1 -> 0.066655165 | J10: 2021 | K10: 2822.12 | L10: =K10/K9-1 -> -0.025648993 | N10: 2021 | O10: 91.63 | P10: =O10/O9-1 -> -0.10456367 | R10: 2021 | S10: 791.27 | T10: =S10/S9-1 -> 0.013798847
B11: 2022 | C11: 29101.28 | D11: =C11/C10-1 -> 0.34028285 | F11: 2022 | G11: 20590.57 | H11: =G11/G10-1 -> 0.46707996 | J11: 2022 | K11: 3707.1 | L11: =K11/K10-1 -> 0.31358695 | N11: 2022 | O11: 95.41 | P11: =O11/O10-1 -> 0.041252865 | R11: 2022 | S11: 816.36 | T11: =S11/S10-1 -> 0.031708519
B12: 2023 | C12: 34488.59 | D12: =C12/C11-1 -> 0.18512278 | F12: 2023 | G12: 23766.7 | H12: =G12/G11-1 -> 0.15425168 | J12: 2023 | K12: 4462.05 | L12: =K12/K11-1 -> 0.20364975 | N12: 2023 | O12: 144.45 | P12: =O12/O11-1 -> 0.51399224 | R12: 2023 | S12: 858.02 | T12: =S12/S11-1 -> 0.051031408
B13: 2024 | C13: 35494.73 | D13: =C13/C12-1 -> 0.029173127 | F13: 2024 | G13: 23009.99 | H13: =G13/G12-1 -> -0.031839086 | J13: 2024 | K13: 4899.76 | L13: =K13/K12-1 -> 0.098096167 | N13: 2024 | O13: 205.17 | P13: =O13/O12-1 -> 0.42035306 | R13: 2024 | S13: 853 | T13: =S13/S12-1 -> -0.0058506795
B14: 2025 | C14: 33905.62 | D14: =C14/C13-1 -> -0.044770308 | F14: 2025 | G14: 22741.27 | H14: =G14/G13-1 -> -0.011678406 | J14: 2025 | K14: 5158.14 | L14: =K14/K13-1 -> 0.052733195 | N14: 2025 | O14: 227.02 | P14: =O14/O13-1 -> 0.10649705 | R14: 2025 | S14: 1026.34 | T14: =S14/S13-1 -> 0.20321219
B15: 2026 | C15: =FORECAST(B15,_xlfn.ANCHORARRAY($C$5),$B$5:B14) -> 38669.293 | D15: =C15/C14-1 -> 0.14049805 | F15: 2026 | G15: =FORECAST(F15,$G$5:G14,$F$5:F14) -> 26044.215 | H15: =G15/G14-1 -> 0.14524014 | J15: 2026 | K15: =FORECAST(J15,$K$5:K14,$J$5:J14) -> 5297.4967 | L15: =K15/K14-1 -> 0.027016845 | N15: 2026 | O15: =FORECAST(N15,$O$5:O14,$N$5:N14) -> 218.29733 | P15: =O15/O14-1 -> -0.038422459 | R15: 2026 | S15: =FORECAST(R15,$S$5:S14,$R$5:R14) -> 1120.6967 | T15: =S15/S14-1 -> 0.091935096
