Workbook
Name UPDATE: 'Data Sheet'!$E$1

Sheet Financials>

Sheet One Page Profile
B2: ='Data Sheet'!B1& " - "& "One Page Profile" -> ITC LTD - One Page Profile
C4: =Input!C2 -> ITC Limited is an Indian conglomerate, headquartered in Kolkata. It has a presence across six business segments, namely FMCG, agribusiness, information technology, paper products, and packaging. It generates a plurality of its revenue from tobacco products. In terms of market capitalization, ITC is the second largest FMCG company in India and the third-largest tobacco company in the world. It employs 36,500 people at more than 60 locations across India.
B5: (INR Crs.)
B6: Key Financial Metrics | C6: ='Data Sheet'!G$16 -> 44286 | D6: ='Data Sheet'!H$16 -> 44651 | E6: ='Data Sheet'!I$16 -> 45016 | F6: ='Data Sheet'!J$16 -> 45382 | G6: ='Data Sheet'!K$16 -> 45747 | I6: Share Price - 5Y
B8: Total Sales | C8: ='Data Sheet'!G17 -> 49257.45 | D8: ='Data Sheet'!H17 -> 60644.54 | E8: ='Data Sheet'!I17 -> 70919.03 | F8: ='Data Sheet'!J17 -> 67931.94 | G8: ='Data Sheet'!K17 -> 75323.34
B9: Sales Growth (Y-on-Y) | C9: ='Ratio Analysis'!H10 -> -0.0026372963 | D9: ='Ratio Analysis'!I10 -> 0.23117498 | E9: ='Ratio Analysis'!J10 -> 0.16942152 | F9: ='Ratio Analysis'!K10 -> -0.042119724 | G9: ='Ratio Analysis'!L10 -> 0.10880596
B10: Gross Profit Margins (%) | C10: ='Ratio Analysis'!H17 -> 0.45426509 | D10: ='Ratio Analysis'!I17 -> 0.43848102 | E10: ='Ratio Analysis'!J17 -> 0.45991746 | F10: ='Ratio Analysis'!K17 -> 0.47497466 | G10: ='Ratio Analysis'!L17 -> 0.44945073
B11: EBIDTA Margins (%) | C11: ='Ratio Analysis'!H18 -> 0.34644059 | D11: ='Ratio Analysis'!I18 -> 0.34006606 | E11: ='Ratio Analysis'!J18 -> 0.36244517 | F11: ='Ratio Analysis'!K18 -> 0.37077596 | G11: ='Ratio Analysis'!L18 -> 0.34304706
B12: EBIT Margins | C12: ='Ratio Analysis'!H19 -> 0.31303265 | D12: ='Ratio Analysis'!I19 -> 0.31149944 | E12: ='Ratio Analysis'!J19 -> 0.33693707 | F12: ='Ratio Analysis'!K19 -> 0.34842932 | G12: ='Ratio Analysis'!L19 -> 0.32119035
B13: Net Profit Margins (%) | C13: ='Ratio Analysis'!H21 -> 0.21937656 | D13: ='Ratio Analysis'!I21 -> 0.22414895 | E13: ='Ratio Analysis'!J21 -> 0.24505524 | F13: ='Ratio Analysis'!K21 -> 0.25644653 | G13: ='Ratio Analysis'!L21 -> 0.22911358
B14: Earning Per Share (In Rs) | C14: =HistoricalFS!H45 -> 8.779028 | D14: =HistoricalFS!I45 -> 11.030657 | E14: =HistoricalFS!J45 -> 13.983811 | F14: =HistoricalFS!K45 -> 13.953807 | G14: =HistoricalFS!L45 -> 13.790524
B15: EPS Growth (Y-on-Y) | C15: =HistoricalFS!H46 -> 0.81904972 | D15: =HistoricalFS!I46 -> 1.2564782 | E15: =HistoricalFS!J46 -> 1.2677223 | F15: =HistoricalFS!K46 -> 0.99785443 | G15: =HistoricalFS!L46 -> 0.98829831
B16: Dividend Per Share (In Rs) | C16: =HistoricalFS!H48 -> 10.75 | D16: =HistoricalFS!I48 -> 11.500004 | E16: =HistoricalFS!J48 -> 15.5 | F16: =HistoricalFS!K48 -> 13.749998 | G16: =HistoricalFS!L48 -> 14.349997
B17: DPS Growth (Y-on-Y) | C17: =HistoricalFS!H49 -> 1.2245091 | D17: =HistoricalFS!I49 -> 1.0425493 | E17: =HistoricalFS!J49 -> 1.1084246 | F17: =HistoricalFS!K49 -> 0.98539399 | G17: =HistoricalFS!L49 -> 1.0405694
B19: Key Financial Ratios | C19: ='Data Sheet'!G$16 -> 44286 | D19: ='Data Sheet'!H$16 -> 44651 | E19: ='Data Sheet'!I$16 -> 45016 | F19: ='Data Sheet'!J$16 -> 45382 | G19: ='Data Sheet'!K$16 -> 45747 | I19: Volume - 5Y
B21: =Input!B14 -> Price to Earning | C21: =Input!H14 -> 23.330601 | D21: =Input!I14 -> 21.300634 | E21: =Input!J14 -> 25.707585 | F21: =Input!K14 -> 28.775659 | G21: =Input!L14 -> 29.712431
B22: =Input!B9 -> EV/EBITDA | C22: =Input!C9 -> 16.627944 | D22: =Input!D9 -> 20.443521 | E22: =Input!E9 -> 17.519308 | F22: =Input!F9 -> 18.202942 | G22: =Input!G9 -> 9.8659847
B23: =Input!B10 -> EV/Sales | C23: =Input!C10 -> 6.1652425 | D23: =Input!D10 -> 7.3946458 | E23: =Input!E10 -> 6.6613663 | F23: =Input!F10 -> 6.9805125 | G23: =Input!G10 -> 3.8641822
B24: =Input!B12 -> Price to Book Value | C24: =Input!C12 -> 5.8015723 | D24: =Input!D12 -> 6.8768107 | E24: =Input!E12 -> 5.5664135 | F24: =Input!F12 -> 5.7755936 | G24: =Input!G12 -> 3.0309955
B25: Return on Equity (%) | C25: ='Ratio Analysis'!H29 -> 0.17906224 | D25: ='Ratio Analysis'!I29 -> 0.21764928 | E25: ='Ratio Analysis'!J29 -> 0.25130525 | F25: ='Ratio Analysis'!K29 -> 0.23381575 | G25: ='Ratio Analysis'!L29 -> 0.24643135
B26: Return on Capital Employed (%) | C26: ='Ratio Analysis'!H27 -> 0.25436581 | D26: ='Ratio Analysis'!I27 -> 0.30126365 | E26: ='Ratio Analysis'!J27 -> 0.3440081 | F26: ='Ratio Analysis'!K27 -> 0.31639278 | G26: ='Ratio Analysis'!L27 -> 0.34406984
B28: Top Shareholders | C28: Shares Held (Crs.) | E28: % Holdings | F28: Market Value (Crs.) | I28: Shareholding Pattern
B30: =Input!B17 -> Tobacco Manufacturers Ltd. | C30: =Input!C17 -> 222.84959 | E30: =Input!D17 -> 0.1781 | F30: =Input!E17 -> 91312.618
B31: =Input!B18 -> Life Insurance Corporation of India | C31: =Input!C18 -> 197.70109 | E31: =Input!D18 -> 0.158 | F31: =Input!E18 -> 81008.021
B32: =Input!B19 -> SUUTI | C32: =Input!C19 -> 97.453143 | E32: =Input!D19 -> 0.0779 | F32: =Input!E19 -> 39931.425
B33: =Input!B20 -> Myddleton Investment Company Ltd | C33: =Input!C20 -> 48.631194 | E33: =Input!D20 -> 0.0389 | F33: =Input!E20 -> 19926.632
B34: =Input!B21 -> SBI Mutual Funds | C34: =Input!C21 -> 43.517441 | E34: =Input!D21 -> 0.0348 | F34: =Input!E21 -> 17831.272
B35: =Input!B22 -> ICICI Prudential Mutual Funds | C35: =Input!C22 -> 27.619721 | E35: =Input!D22 -> 0.0221 | F35: =Input!E22 -> 11317.181
B36: =Input!B23 -> GQG Partners Equity Fund | C36: =Input!C23 -> 26.390174 | E36: =Input!D23 -> 0.0211 | F36: =Input!E23 -> 10813.374
B38: Managerial Remuneration | C38: Designation | D38: Remuneration (Lakh) | F38: X of Median Salary | I38: Capital Structure
B40: Mr. Sanjeev Puri | C40: CMD | D40: 2566.47 | F40: 377 | I40: Share Price (03-09-2025) | K40: ='Data Sheet'!B8 -> 409.75
B41: Mr. Supratim Dutta | C41: ED & CFO | D41: 853.14 | F41: 132 | I41: Number of Shares O/S | K41: ='Data Sheet'!B6 -> 1252.6663
B42: Mr. Hemant Malik | C42: ED | D42: 494.13 | F42: 99 | I42: Market Capitalization | K42: =K40*K41 -> 513280.01
B43: Mr. B Sumant | C43: ED | D43: 1181.4 | F43: 174 | I43: Less: Cash & Equivalents | K43: =-'Data Sheet'!K69 -> -4012.36
B44: Mr. H Bharagva | C44: Indep. Director | D44: 104.1 | F44: 14 | I44: Add: Total Debt | K44: ='Data Sheet'!K59 -> 284.54
B45: Mr. A M Bharucha | C45: Indep. Director | D45: 66.8 | F45: 9 | I45: Add: Minority Interest | K45: ='Raw Bs'!L12 -> 368
B46: Mr. C K Mishra | C46: Indep. Director | D46: 3 | F46: 9 | I46: Enterprise Value | K46: =K42+K43+K44+K45 -> 509920.19
B48: Peer Comparison (FMCG Industry)
B49: Companies | C49: ='Comps Data'!E2 -> CMP (INR) | D49: ='Comps Data'!G2 -> Market Capitalization | F49: ='Comps Data'!H2 -> Debt | G49: ='Comps Data'!I2 -> Cash at End | I49: ='Comps Data'!K2 -> Sales | J49: ='Comps Data'!N2 -> ROE % | K49: ='Comps Data'!O2 -> ROCE %
B51: ='Comps Data'!C4 -> Hind. Unilever | C51: ='Comps Data'!E4 -> 2659.8 | D51: ='Comps Data'!G4 -> 624946.61 | F51: ='Comps Data'!H4 -> 1648 | G51: ='Comps Data'!I4 -> 7554 | I51: ='Comps Data'!K4 -> 63928 | J51: ='Comps Data'!N4 -> 0.2732 | K51: ='Comps Data'!O4 -> 0.3679
...

Sheet HistoricalFS
B2: ='Data Sheet'!B1 -> ITC LTD
B3: (ITC | BSE Code: 540376)
B4: =CONCATENATE("INR"," ", 'Data Sheet'!B8) -> INR 409.75
B5: 52 Week (High - INR 410.45 & Low - INR 401.90)
B7: ="Historical Financials Statements - "&'Data Sheet'!B1 -> Historical Financials Statements - ITC LTD
B8: Years | C8: ='Data Sheet'!B16 -> 42460 | D8: ='Data Sheet'!C16 -> 42825 | E8: ='Data Sheet'!D16 -> 43190 | F8: ='Data Sheet'!E16 -> 43555 | G8: ='Data Sheet'!F16 -> 43921 | H8: ='Data Sheet'!G16 -> 44286 | I8: ='Data Sheet'!H16 -> 44651 | J8: ='Data Sheet'!I16 -> 45016 | ... L8: ='Data Sheet'!K16 -> 45747
A9: # | B9: Income Statement
B10: Sales | C10: =IFERROR('Data Sheet'!B17,0) -> 39192.1 | D10: =IFERROR('Data Sheet'!C17,0) -> 42767.6 | E10: =IFERROR('Data Sheet'!D17,0) -> 43448.94 | F10: =IFERROR('Data Sheet'!E17,0) -> 48339.58 | G10: =IFERROR('Data Sheet'!F17,0) -> 49387.7 | H10: =IFERROR('Data Sheet'!G17,0) -> 49257.45 | I10: =IFERROR('Data Sheet'!H17,0) -> 60644.54 | J10: =IFERROR('Data Sheet'!I17,0) -> 70919.03 | ... L10: =IFERROR('Data Sheet'!K17,0) -> 75323.34
B11: Sales Growth % | C11: - | D11: =D10/C10-1 -> 0.09123012 | E11: =E10/D10-1 -> 0.015931219 | F11: =F10/E10-1 -> 0.11256063 | G11: =G10/F10-1 -> 0.021682439 | H11: =H10/G10-1 -> -0.0026372963 | I11: =I10/H10-1 -> 0.23117498 | J11: =J10/I10-1 -> 0.16942152 | K11: =K10/J10-1 -> -0.042119724 | L11: =L10/K10-1 -> 0.10880596
B13: COGS | C13: =IFERROR(SUM('Data Sheet'!B18,'Data Sheet'!B20:B22)-1*'Data Sheet'!B19,0) -> 19162.94 | D13: =IFERROR(SUM('Data Sheet'!C18,'Data Sheet'!C20:C22)-1*'Data Sheet'!C19,0) -> 21949.12 | E13: =IFERROR(SUM('Data Sheet'!D18,'Data Sheet'!D20:D22)-1*'Data Sheet'!D19,0) -> 21967.5 | F13: =IFERROR(SUM('Data Sheet'!E18,'Data Sheet'!E20:E22)-1*'Data Sheet'!E19,0) -> 24215.95 | G13: =IFERROR(SUM('Data Sheet'!F18,'Data Sheet'!F20:F22)-1*'Data Sheet'!F19,0) -> 24330.4 | H13: =IFERROR(SUM('Data Sheet'!G18,'Data Sheet'!G20:G22)-1*'Data Sheet'!G19,0) -> 26881.51 | I13: =IFERROR(SUM('Data Sheet'!H18,'Data Sheet'!H20:H22)-1*'Data Sheet'!H19,0) -> 34053.06 | J13: =IFERROR(SUM('Data Sheet'!I18,'Data Sheet'!I20:I22)-1*'Data Sheet'!I19,0) -> 38302.13 | ... L13: =IFERROR(SUM('Data Sheet'!K18,'Data Sheet'!K20:K22)-1*'Data Sheet'!K19,0) -> 41469.21
B14: COGS % of Sales | C14: =C13/C10 -> 0.48894905 | D14: =D13/D10 -> 0.51321842 | E14: =E13/E10 -> 0.50559346 | F14: =F13/F10 -> 0.50095491 | G14: =G13/G10 -> 0.49264088 | H14: =H13/H10 -> 0.54573491 | I14: =I13/I10 -> 0.56151898 | J14: =J13/J10 -> 0.54008254 | ... L14: =L13/L10 -> 0.55054927
B16: Gross Profit | C16: =C10-C13 -> 20029.16 | D16: =D10-D13 -> 20818.48 | E16: =E10-E13 -> 21481.44 | F16: =F10-F13 -> 24123.63 | G16: =G10-G13 -> 25057.3 | H16: =H10-H13 -> 22375.94 | I16: =I10-I13 -> 26591.48 | J16: =J10-J13 -> 32616.9 | ... L16: =L10-L13 -> 33854.13
B17: Gross Margins | C17: =C16/C10 -> 0.51105095 | D17: =D16/D10 -> 0.48678158 | E17: =E16/E10 -> 0.49440654 | F17: =F16/F10 -> 0.49904509 | G17: =G16/G10 -> 0.50735912 | H17: =H16/H10 -> 0.45426509 | I17: =I16/I10 -> 0.43848102 | J17: =J16/J10 -> 0.45991746 | ... L17: =L16/L10 -> 0.44945073
B19: Selling & General Expenses | C19: =IFERROR(SUM('Data Sheet'!B23:B24),0) -> 5497.67 | D19: =IFERROR(SUM('Data Sheet'!C23:C24),0) -> 5348.97 | E19: =IFERROR(SUM('Data Sheet'!D23:D24),0) -> 4960.85 | F19: =IFERROR(SUM('Data Sheet'!E23:E24),0) -> 5586.24 | G19: =IFERROR(SUM('Data Sheet'!F23:F24),0) -> 5713.76 | H19: =IFERROR(SUM('Data Sheet'!G23:G24),0) -> 5311.16 | I19: =IFERROR(SUM('Data Sheet'!H23:H24),0) -> 5968.33 | J19: =IFERROR(SUM('Data Sheet'!I23:I24),0) -> 6912.64 | ... L19: =IFERROR(SUM('Data Sheet'!K23:K24),0) -> 8014.68
B20: S&G Exp % of Sales | C20: =C19/C10 -> 0.14027495 | D20: =D19/D10 -> 0.12507061 | E20: =E19/E10 -> 0.11417655 | F20: =F19/F10 -> 0.11556244 | G20: =G19/G10 -> 0.11569196 | H20: =H19/H10 -> 0.1078245 | I20: =I19/I10 -> 0.09841496 | J20: =J19/J10 -> 0.097472286 | ... L20: =L19/L10 -> 0.10640367
B22: EBITDA | C22: =C16-C19 -> 14531.49 | D22: =D16-D19 -> 15469.51 | E22: =E16-E19 -> 16520.59 | F22: =F16-F19 -> 18537.39 | G22: =G16-G19 -> 19343.54 | H22: =H16-H19 -> 17064.78 | I22: =I16-I19 -> 20623.15 | J22: =J16-J19 -> 25704.26 | ... L22: =L16-L19 -> 25839.45
B23: EBITDA % of Sales | C23: =C22/C10 -> 0.370776 | D23: =D22/D10 -> 0.36171097 | E23: =E22/E10 -> 0.38022999 | F23: =F22/F10 -> 0.38348265 | G23: =G22/G10 -> 0.39166716 | H23: =H22/H10 -> 0.34644059 | I23: =I22/I10 -> 0.34006606 | J23: =J22/J10 -> 0.36244517 | ... L23: =L22/L10 -> 0.34304706
B25: Interest | C25: =IFERROR('Data Sheet'!B27,0) -> 78.13 | D25: =IFERROR('Data Sheet'!C27,0) -> 49.03 | E25: =IFERROR('Data Sheet'!D27,0) -> 115.01 | F25: =IFERROR('Data Sheet'!E27,0) -> 71.4 | G25: =IFERROR('Data Sheet'!F27,0) -> 81.38 | H25: =IFERROR('Data Sheet'!G27,0) -> 57.97 | I25: =IFERROR('Data Sheet'!H27,0) -> 59.99 | J25: =IFERROR('Data Sheet'!I27,0) -> 77.77 | ... L25: =IFERROR('Data Sheet'!K27,0) -> 45.06
B26: Interest % of Sales | C26: =C25/C10 -> 0.001993514 | D26: =D25/D10 -> 0.0011464286 | E26: =E25/E10 -> 0.0026470151 | F26: =F25/F10 -> 0.0014770505 | G26: =G25/G10 -> 0.0016477787 | H26: =H25/H10 -> 0.0011768778 | I26: =I25/I10 -> 0.00098920694 | J26: =J25/J10 -> 0.0010966027 | ... L26: =L25/L10 -> 0.00059822095
B28: Depriciation | C28: =IFERROR('Data Sheet'!B26,0) -> 1077.4 | D28: =IFERROR('Data Sheet'!C26,0) -> 1152.79 | E28: =IFERROR('Data Sheet'!D26,0) -> 1236.28 | F28: =IFERROR('Data Sheet'!E26,0) -> 1396.61 | G28: =IFERROR('Data Sheet'!F26,0) -> 1644.91 | H28: =IFERROR('Data Sheet'!G26,0) -> 1645.59 | I28: =IFERROR('Data Sheet'!H26,0) -> 1732.41 | J28: =IFERROR('Data Sheet'!I26,0) -> 1809.01 | ... L28: =IFERROR('Data Sheet'!K26,0) -> 1646.32
B29: Depriciation % of Sales | C29: =C28/C10 -> 0.027490234 | D29: =D28/D10 -> 0.026954751 | E29: =E28/E10 -> 0.028453629 | F29: =F28/F10 -> 0.028891645 | G29: =G28/G10 -> 0.033306066 | H29: =H28/H10 -> 0.033407941 | I29: =I28/I10 -> 0.028566628 | J29: =J28/J10 -> 0.025508104 | ... L29: =L28/L10 -> 0.021856705
B31: EBIT | C31: =C22-C28 -> 13454.09 | D31: =D22-D28 -> 14316.72 | E31: =E22-E28 -> 15284.31 | F31: =F22-F28 -> 17140.78 | G31: =G22-G28 -> 17698.63 | H31: =H22-H28 -> 15419.19 | I31: =I22-I28 -> 18890.74 | J31: =J22-J28 -> 23895.25 | ... L31: =L22-L28 -> 24193.13
B32: EBIT % of Sales | C32: =IFERROR(C31/C10,0) -> 0.34328576 | D32: =IFERROR(D31/D10,0) -> 0.33475622 | E32: =IFERROR(E31/E10,0) -> 0.35177636 | F32: =IFERROR(F31/F10,0) -> 0.354591 | G32: =IFERROR(G31/G10,0) -> 0.35836109 | H32: =IFERROR(H31/H10,0) -> 0.31303265 | I32: =IFERROR(I31/I10,0) -> 0.31149944 | J32: =IFERROR(J31/J10,0) -> 0.33693707 | ... L32: =IFERROR(L31/L10,0) -> 0.32119035
B34: EBT | C34: =IFERROR(C22-SUM(C25,C28),0) -> 13375.96 | D34: =IFERROR(D22-SUM(D25,D28),0) -> 14267.69 | E34: =IFERROR(E22-SUM(E25,E28),0) -> 15169.3 | F34: =IFERROR(F22-SUM(F25,F28),0) -> 17069.38 | G34: =IFERROR(G22-SUM(G25,G28),0) -> 17617.25 | H34: =IFERROR(H22-SUM(H25,H28),0) -> 15361.22 | I34: =IFERROR(I22-SUM(I25,I28),0) -> 18830.75 | J34: =IFERROR(J22-SUM(J25,J28),0) -> 23817.48 | ... L34: =IFERROR(L22-SUM(L25,L28),0) -> 24148.07
B35: EBT % of Sales | C35: =C34/C10 -> 0.34129225 | D35: =D34/D10 -> 0.33360979 | E35: =E34/E10 -> 0.34912935 | F35: =F34/F10 -> 0.35311395 | G35: =G34/G10 -> 0.35671331 | H35: =H34/H10 -> 0.31185577 | I35: =I34/I10 -> 0.31051023 | J35: =J34/J10 -> 0.33584046 | ... L35: =L34/L10 -> 0.32059213
B37: Tax | C37: =IFERROR('Data Sheet'!B29,0) -> 5358.21 | D37: =IFERROR('Data Sheet'!C29,0) -> 5549.09 | E37: =IFERROR('Data Sheet'!D29,0) -> 5916.43 | F37: =IFERROR('Data Sheet'!E29,0) -> 6313.92 | G37: =IFERROR('Data Sheet'!F29,0) -> 4441.79 | H37: =IFERROR('Data Sheet'!G29,0) -> 4555.29 | I37: =IFERROR('Data Sheet'!H29,0) -> 5237.34 | J37: =IFERROR('Data Sheet'!I29,0) -> 6438.4 | ... L37: =IFERROR('Data Sheet'!K29,0) -> 6890.47
B38: Effective Tax Rate | C38: =C37/C34 -> 0.40058508 | D38: =D37/D34 -> 0.38892701 | E38: =E37/E34 -> 0.39002657 | F38: =F37/F34 -> 0.36989744 | G38: =G37/G34 -> 0.25212732 | H38: =H37/H34 -> 0.29654481 | I38: =I37/I34 -> 0.278127 | J38: =J37/J34 -> 0.27032247 | ... L38: =L37/L34 -> 0.28534247
B40: Net Profit | C40: =C34-C37 -> 8017.75 | D40: =D34-D37 -> 8718.6 | E40: =E34-E37 -> 9252.87 | F40: =F34-F37 -> 10755.46 | G40: =G34-G37 -> 13175.46 | H40: =H34-H37 -> 10805.93 | I40: =I34-I37 -> 13593.41 | J40: =J34-J37 -> 17379.08 | ... L40: =L34-L37 -> 17257.6
B41: Net Margins | C41: =C40/C10 -> 0.20457567 | D41: =D40/D10 -> 0.20385993 | E41: =E40/E10 -> 0.21295963 | F41: =F40/F10 -> 0.222498 | G41: =G40/G10 -> 0.26677614 | H41: =H40/H10 -> 0.21937656 | I41: =I40/I10 -> 0.22414895 | J41: =J40/J10 -> 0.24505524 | ... L41: =L40/L10 -> 0.22911358
B43: No. of Equity Shares | C43: =IFERROR('Data Sheet'!B93,0) -> 1207.08 | D43: =IFERROR('Data Sheet'!C93,0) -> 1214.74 | E43: =IFERROR('Data Sheet'!D93,0) -> 1220.43 | F43: =IFERROR('Data Sheet'!E93,0) -> 1225.86 | G43: =IFERROR('Data Sheet'!F93,0) -> 1229.22 | H43: =IFERROR('Data Sheet'!G93,0) -> 1230.88 | I43: =IFERROR('Data Sheet'!H93,0) -> 1232.33 | J43: =IFERROR('Data Sheet'!I93,0) -> 1242.8 | ... L43: =IFERROR('Data Sheet'!K93,0) -> 1251.41
B45: EPS | C45: =IFERROR(C40/C43,0) -> 6.6422689 | D45: =IFERROR(D40/D43,0) -> 7.1773384 | E45: =IFERROR(E40/E43,0) -> 7.5816475 | F45: =IFERROR(F40/F43,0) -> 8.7738078 | G45: =IFERROR(G40/G43,0) -> 10.718553 | H45: =IFERROR(H40/H43,0) -> 8.779028 | I45: =IFERROR(I40/I43,0) -> 11.030657 | J45: =IFERROR(J40/J43,0) -> 13.983811 | ... L45: =IFERROR(L40/L43,0) -> 13.790524
B46: EPS Growth % | C46: - | D46: =IFERROR(D45/C45,0) -> 1.0805552 | E46: =IFERROR(E45/D45,0) -> 1.0563313 | F46: =IFERROR(F45/E45,0) -> 1.1572429 | G46: =IFERROR(G45/F45,0) -> 1.2216535 | H46: =IFERROR(H45/G45,0) -> 0.81904972 | I46: =IFERROR(I45/H45,0) -> 1.2564782 | J46: =IFERROR(J45/I45,0) -> 1.2677223 | K46: =IFERROR(K45/J45,0) -> 0.99785443 | L46: =IFERROR(L45/K45,0) -> 0.98829831
B48: Divided per Share | C48: =IFERROR('Data Sheet'!B31/HistoricalFS!C43,0) -> 5.6666667 | D48: =IFERROR('Data Sheet'!C31/HistoricalFS!D43,0) -> 4.7500041 | E48: =IFERROR('Data Sheet'!D31/HistoricalFS!E43,0) -> 5.1499963 | F48: =IFERROR('Data Sheet'!E31/HistoricalFS!F43,0) -> 5.7500041 | G48: =IFERROR('Data Sheet'!F31/HistoricalFS!G43,0) -> 10.149998 | H48: =IFERROR('Data Sheet'!G31/HistoricalFS!H43,0) -> 10.75 | I48: =IFERROR('Data Sheet'!H31/HistoricalFS!I43,0) -> 11.500004 | J48: =IFERROR('Data Sheet'!I31/HistoricalFS!J43,0) -> 15.5 | ... L48: =IFERROR('Data Sheet'!K31/HistoricalFS!L43,0) -> 14.349997
B49: Dividend Payout Ratio | C49: =IFERROR(C48/C45,0) -> 0.85312214 | D49: =IFERROR(D48/D45,0) -> 0.66180579 | E49: =IFERROR(E48/E45,0) -> 0.6792714 | F49: =IFERROR(F48/F45,0) -> 0.65536016 | G49: =IFERROR(G48/G45,0) -> 0.94695593 | H49: =IFERROR(H48/H45,0) -> 1.2245091 | I49: =IFERROR(I48/I45,0) -> 1.0425493 | J49: =IFERROR(J48/J45,0) -> 1.1084246 | ... L49: =IFERROR(L48/L45,0) -> 1.0405694
B51: Retained Earnings | C51: =IFERROR(IF(C45>C48,1-C49,0),0) -> 0.14687786 | D51: =IFERROR(IF(D45>D48,1-D49,0),0) -> 0.33819421 | E51: =IFERROR(IF(E45>E48,1-E49,0),0) -> 0.3207286 | F51: =IFERROR(IF(F45>F48,1-F49,0),0) -> 0.34463984 | G51: =IFERROR(IF(G45>G48,1-G49,0),0) -> 0.053044068 | H51: =IFERROR(IF(H45>H48,1-H49,0),0) -> 0 | I51: =IFERROR(IF(I45>I48,1-I49,0),0) -> 0 | J51: =IFERROR(IF(J45>J48,1-J49,0),0) -> 0 | ... L51: =IFERROR(IF(L45>L48,1-L49,0),0) -> 0
A53: # | B53: Balance Sheet
B54: Equity Share Capital | C54: =IFERROR('Data Sheet'!B57,0) -> 804.72 | D54: =IFERROR('Data Sheet'!C57,0) -> 1214.74 | E54: =IFERROR('Data Sheet'!D57,0) -> 1220.43 | F54: =IFERROR('Data Sheet'!E57,0) -> 1225.86 | G54: =IFERROR('Data Sheet'!F57,0) -> 1229.22 | H54: =IFERROR('Data Sheet'!G57,0) -> 1230.88 | I54: =IFERROR('Data Sheet'!H57,0) -> 1232.33 | J54: =IFERROR('Data Sheet'!I57,0) -> 1242.8 | ... L54: =IFERROR('Data Sheet'!K57,0) -> 1251.41
B55: Reserves | C55: =IFERROR('Data Sheet'!B58,0) -> 41874.8 | D55: =IFERROR('Data Sheet'!C58,0) -> 45198.19 | E55: =IFERROR('Data Sheet'!D58,0) -> 51289.68 | F55: =IFERROR('Data Sheet'!E58,0) -> 57915.01 | G55: =IFERROR('Data Sheet'!F58,0) -> 64044.04 | H55: =IFERROR('Data Sheet'!G58,0) -> 59116.46 | I55: =IFERROR('Data Sheet'!H58,0) -> 61223.24 | J55: =IFERROR('Data Sheet'!I58,0) -> 67912.46 | ... L55: =IFERROR('Data Sheet'!K58,0) -> 68778.64
B56: Borrowings | C56: =IFERROR('Data Sheet'!B59,0) -> 83.78 | D56: =IFERROR('Data Sheet'!C59,0) -> 45.72 | E56: =IFERROR('Data Sheet'!D59,0) -> 35.92 | F56: =IFERROR('Data Sheet'!E59,0) -> 13.44 | G56: =IFERROR('Data Sheet'!F59,0) -> 277.45 | H56: =IFERROR('Data Sheet'!G59,0) -> 270.83 | I56: =IFERROR('Data Sheet'!H59,0) -> 249.44 | J56: =IFERROR('Data Sheet'!I59,0) -> 306.04 | ... L56: =IFERROR('Data Sheet'!K59,0) -> 284.54
B57: Other Liabilities | C57: =IFERROR('Data Sheet'!B60,0) -> 8888.04 | D57: =IFERROR('Data Sheet'!C60,0) -> 9439.67 | E57: =IFERROR('Data Sheet'!D60,0) -> 11694.85 | F57: =IFERROR('Data Sheet'!E60,0) -> 12584.73 | G57: =IFERROR('Data Sheet'!F60,0) -> 11760.04 | H57: =IFERROR('Data Sheet'!G60,0) -> 13142.59 | I57: =IFERROR('Data Sheet'!H60,0) -> 14491.01 | J57: =IFERROR('Data Sheet'!I60,0) -> 16369.66 | ... L57: =IFERROR('Data Sheet'!K60,0) -> 17688.11
...

Sheet Common Size Statement
B2: ='Data Sheet'!B1 -> ITC LTD
B3: (ITC | BSE Code: 540376)
B4: =CONCATENATE("INR"," ", 'Data Sheet'!B8) -> INR 409.75
B5: 52 Week (High - INR 410.45 & Low - INR 401.90)
A7: # | B7: ="Common Size Income Statement - "&'Data Sheet'!$B$1 -> Common Size Income Statement - ITC LTD
B8: Particulars | C8: ='Data Sheet'!B$16 -> 42460 | D8: ='Data Sheet'!C$16 -> 42825 | E8: ='Data Sheet'!D$16 -> 43190 | F8: ='Data Sheet'!E$16 -> 43555 | G8: ='Data Sheet'!F$16 -> 43921 | H8: ='Data Sheet'!G$16 -> 44286 | I8: ='Data Sheet'!H$16 -> 44651 | J8: ='Data Sheet'!I$16 -> 45016 | ... L8: ='Data Sheet'!K$16 -> 45747
B10: ='Data Sheet'!A17 -> Sales | C10: ='Data Sheet'!B17/'Data Sheet'!B$17 -> 1 | D10: ='Data Sheet'!C17/'Data Sheet'!C$17 -> 1 | E10: ='Data Sheet'!D17/'Data Sheet'!D$17 -> 1 | F10: ='Data Sheet'!E17/'Data Sheet'!E$17 -> 1 | G10: ='Data Sheet'!F17/'Data Sheet'!F$17 -> 1 | H10: ='Data Sheet'!G17/'Data Sheet'!G$17 -> 1 | I10: ='Data Sheet'!H17/'Data Sheet'!H$17 -> 1 | J10: ='Data Sheet'!I17/'Data Sheet'!I$17 -> 1 | ... L10: ='Data Sheet'!K17/'Data Sheet'!K$17 -> 1
B11: ='Data Sheet'!A18 -> Raw Material Cost | C11: ='Data Sheet'!B18/'Data Sheet'!B$17 -> 0.35119016 | D11: ='Data Sheet'!C18/'Data Sheet'!C$17 -> 0.36140887 | E11: ='Data Sheet'!D18/'Data Sheet'!D$17 -> 0.3412677 | F11: ='Data Sheet'!E18/'Data Sheet'!E$17 -> 0.36457743 | G11: ='Data Sheet'!F18/'Data Sheet'!F$17 -> 0.36544727 | H11: ='Data Sheet'!G18/'Data Sheet'!G$17 -> 0.42179833 | I11: ='Data Sheet'!H18/'Data Sheet'!H$17 -> 0.44638924 | J11: ='Data Sheet'!I18/'Data Sheet'!I$17 -> 0.41405473 | ... L11: ='Data Sheet'!K18/'Data Sheet'!K$17 -> 0.4341864
B12: ='Data Sheet'!A19 -> Change in Inventory | C12: ='Data Sheet'!B19/'Data Sheet'!B$17 -> 0.0049851883 | D12: ='Data Sheet'!C19/'Data Sheet'!C$17 -> -0.013855582 | E12: ='Data Sheet'!D19/'Data Sheet'!D$17 -> -0.023654432 | F12: ='Data Sheet'!E19/'Data Sheet'!E$17 -> 0.0042033878 | G12: ='Data Sheet'!F19/'Data Sheet'!F$17 -> 0.014236946 | H12: ='Data Sheet'!G19/'Data Sheet'!G$17 -> 0.013099947 | I12: ='Data Sheet'!H19/'Data Sheet'!H$17 -> 0.011311818 | J12: ='Data Sheet'!I19/'Data Sheet'!I$17 -> 0.0050563297 | ... L12: ='Data Sheet'!K19/'Data Sheet'!K$17 -> 0.0096338001
B13: ='Data Sheet'!A20 -> Power and Fuel | C13: ='Data Sheet'!B20/'Data Sheet'!B$17 -> 0.014591716 | D13: ='Data Sheet'!C20/'Data Sheet'!C$17 -> 0.013662913 | E13: ='Data Sheet'!D20/'Data Sheet'!D$17 -> 0.015040643 | F13: ='Data Sheet'!E20/'Data Sheet'!E$17 -> 0.01544759 | G13: ='Data Sheet'!F20/'Data Sheet'!F$17 -> 0.015810617 | H13: ='Data Sheet'!G20/'Data Sheet'!G$17 -> 0.014202116 | I13: ='Data Sheet'!H20/'Data Sheet'!H$17 -> 0.01467189 | J13: ='Data Sheet'!I20/'Data Sheet'!I$17 -> 0.017376718 | ... L13: ='Data Sheet'!K20/'Data Sheet'!K$17 -> 0.012948842
B14: ='Data Sheet'!A21 -> Other Mfr. Exp | C14: ='Data Sheet'!B21/'Data Sheet'!B$17 -> 0.040354816 | D14: ='Data Sheet'!C21/'Data Sheet'!C$17 -> 0.039373264 | E14: ='Data Sheet'!D21/'Data Sheet'!D$17 -> 0.039071609 | F14: ='Data Sheet'!E21/'Data Sheet'!E$17 -> 0.038705549 | G14: ='Data Sheet'!F21/'Data Sheet'!F$17 -> 0.038638973 | H14: ='Data Sheet'!G21/'Data Sheet'!G$17 -> 0.032222131 | I14: ='Data Sheet'!H21/'Data Sheet'!H$17 -> 0.031126792 | J14: ='Data Sheet'!I21/'Data Sheet'!I$17 -> 0.032823348 | ... L14: ='Data Sheet'!K21/'Data Sheet'!K$17 -> 0.031137228
B15: ='Data Sheet'!A22 -> Employee Cost | C15: ='Data Sheet'!B22/'Data Sheet'!B$17 -> 0.087797541 | D15: ='Data Sheet'!C22/'Data Sheet'!C$17 -> 0.084917788 | E15: ='Data Sheet'!D22/'Data Sheet'!D$17 -> 0.086559074 | F15: ='Data Sheet'!E22/'Data Sheet'!E$17 -> 0.086427727 | G15: ='Data Sheet'!F22/'Data Sheet'!F$17 -> 0.086980969 | H15: ='Data Sheet'!G22/'Data Sheet'!G$17 -> 0.090612283 | I15: ='Data Sheet'!H22/'Data Sheet'!H$17 -> 0.080642874 | J15: ='Data Sheet'!I22/'Data Sheet'!I$17 -> 0.080884073 | ... L15: ='Data Sheet'!K22/'Data Sheet'!K$17 -> 0.0819106
B16: ='Data Sheet'!A23 -> Selling and admin | C16: ='Data Sheet'!B23/'Data Sheet'!B$17 -> 0.10874079 | D16: ='Data Sheet'!C23/'Data Sheet'!C$17 -> 0.09773146 | E16: ='Data Sheet'!D23/'Data Sheet'!D$17 -> 0.091023394 | F16: ='Data Sheet'!E23/'Data Sheet'!E$17 -> 0.094051086 | G16: ='Data Sheet'!F23/'Data Sheet'!F$17 -> 0.090885585 | H16: ='Data Sheet'!G23/'Data Sheet'!G$17 -> 0.086012776 | I16: ='Data Sheet'!H23/'Data Sheet'!H$17 -> 0.080112406 | J16: ='Data Sheet'!I23/'Data Sheet'!I$17 -> 0.079020821 | ... L16: ='Data Sheet'!K23/'Data Sheet'!K$17 -> 0.076912282
B17: ='Data Sheet'!A24 -> Other Expenses | C17: ='Data Sheet'!B24/'Data Sheet'!B$17 -> 0.031534161 | D17: ='Data Sheet'!C24/'Data Sheet'!C$17 -> 0.027339154 | E17: ='Data Sheet'!D24/'Data Sheet'!D$17 -> 0.023153154 | F17: ='Data Sheet'!E24/'Data Sheet'!E$17 -> 0.021511358 | G17: ='Data Sheet'!F24/'Data Sheet'!F$17 -> 0.024806379 | H17: ='Data Sheet'!G24/'Data Sheet'!G$17 -> 0.021811726 | I17: ='Data Sheet'!H24/'Data Sheet'!H$17 -> 0.018302555 | J17: ='Data Sheet'!I24/'Data Sheet'!I$17 -> 0.018451465 | ... L17: ='Data Sheet'!K24/'Data Sheet'!K$17 -> 0.02949139
B18: ='Data Sheet'!A25 -> Other Income | C18: ='Data Sheet'!B25/'Data Sheet'!B$17 -> 0.037842065 | D18: ='Data Sheet'!C25/'Data Sheet'!C$17 -> 0.041120615 | E18: ='Data Sheet'!D25/'Data Sheet'!D$17 -> 0.051550395 | F18: ='Data Sheet'!E25/'Data Sheet'!E$17 -> 0.043038024 | G18: ='Data Sheet'!F25/'Data Sheet'!F$17 -> 0.04894579 | H18: ='Data Sheet'!G25/'Data Sheet'!G$17 -> 0.052315944 | I18: ='Data Sheet'!H25/'Data Sheet'!H$17 -> 0.031490386 | J18: ='Data Sheet'!I25/'Data Sheet'!I$17 -> 0.029577957 | ... L18: ='Data Sheet'!K25/'Data Sheet'!K$17 -> 0.23624656
B19: ='Data Sheet'!A26 -> Depreciation | C19: ='Data Sheet'!B26/'Data Sheet'!B$17 -> 0.027490234 | D19: ='Data Sheet'!C26/'Data Sheet'!C$17 -> 0.026954751 | E19: ='Data Sheet'!D26/'Data Sheet'!D$17 -> 0.028453629 | F19: ='Data Sheet'!E26/'Data Sheet'!E$17 -> 0.028891645 | G19: ='Data Sheet'!F26/'Data Sheet'!F$17 -> 0.033306066 | H19: ='Data Sheet'!G26/'Data Sheet'!G$17 -> 0.033407941 | I19: ='Data Sheet'!H26/'Data Sheet'!H$17 -> 0.028566628 | J19: ='Data Sheet'!I26/'Data Sheet'!I$17 -> 0.025508104 | ... L19: ='Data Sheet'!K26/'Data Sheet'!K$17 -> 0.021856705
B20: ='Data Sheet'!A27 -> Interest | C20: ='Data Sheet'!B27/'Data Sheet'!B$17 -> 0.001993514 | D20: ='Data Sheet'!C27/'Data Sheet'!C$17 -> 0.0011464286 | E20: ='Data Sheet'!D27/'Data Sheet'!D$17 -> 0.0026470151 | F20: ='Data Sheet'!E27/'Data Sheet'!E$17 -> 0.0014770505 | G20: ='Data Sheet'!F27/'Data Sheet'!F$17 -> 0.0016477787 | H20: ='Data Sheet'!G27/'Data Sheet'!G$17 -> 0.0011768778 | I20: ='Data Sheet'!H27/'Data Sheet'!H$17 -> 0.00098920694 | J20: ='Data Sheet'!I27/'Data Sheet'!I$17 -> 0.0010966027 | ... L20: ='Data Sheet'!K27/'Data Sheet'!K$17 -> 0.00059822095
B21: ='Data Sheet'!A28 -> Profit before tax | C21: ='Data Sheet'!B28/'Data Sheet'!B$17 -> 0.37913432 | D21: ='Data Sheet'!C28/'Data Sheet'!C$17 -> 0.3747304 | E21: ='Data Sheet'!D28/'Data Sheet'!D$17 -> 0.40067974 | F21: ='Data Sheet'!E28/'Data Sheet'!E$17 -> 0.39615197 | G21: ='Data Sheet'!F28/'Data Sheet'!F$17 -> 0.4056591 | H21: ='Data Sheet'!G28/'Data Sheet'!G$17 -> 0.36417171 | I21: ='Data Sheet'!H28/'Data Sheet'!H$17 -> 0.34200062 | J21: ='Data Sheet'!I28/'Data Sheet'!I$17 -> 0.36541842 | ... L21: ='Data Sheet'!K28/'Data Sheet'!K$17 -> 0.55683869
... B24: ='Data Sheet'!A31 -> Dividend Amount | C24: ='Data Sheet'!B31/'Data Sheet'!B$17 -> 0.17452803 | D24: ='Data Sheet'!C31/'Data Sheet'!C$17 -> 0.13491568 | E24: ='Data Sheet'!D31/'Data Sheet'!D$17 -> 0.14465738 | F24: ='Data Sheet'!E31/'Data Sheet'!E$17 -> 0.14581633 | G24: ='Data Sheet'!F31/'Data Sheet'!F$17 -> 0.25262525 | H24: ='Data Sheet'!G31/'Data Sheet'!G$17 -> 0.2686286 | I24: ='Data Sheet'!H31/'Data Sheet'!H$17 -> 0.23368633 | J24: ='Data Sheet'!I31/'Data Sheet'!I$17 -> 0.27162526 | ... L24: ='Data Sheet'!K31/'Data Sheet'!K$17 -> 0.23840857
B25: EBITDA | C25: =HistoricalFS!C16/'Data Sheet'!B17 -> 0.51105095 | D25: =HistoricalFS!D16/'Data Sheet'!C17 -> 0.48678158 | E25: =HistoricalFS!E16/'Data Sheet'!D17 -> 0.49440654 | F25: =HistoricalFS!F16/'Data Sheet'!E17 -> 0.49904509 | G25: =HistoricalFS!G16/'Data Sheet'!F17 -> 0.50735912 | H25: =HistoricalFS!H16/'Data Sheet'!G17 -> 0.45426509 | I25: =HistoricalFS!I16/'Data Sheet'!H17 -> 0.43848102 | J25: =HistoricalFS!J16/'Data Sheet'!I17 -> 0.45991746 | ... L25: =HistoricalFS!L16/'Data Sheet'!K17 -> 0.44945073
A27: # | B27: ="Common Size Balance Sheet - "&'Data Sheet'!$B$1 -> Common Size Balance Sheet - ITC LTD
B28: Particulars | C28: ='Data Sheet'!B$16 -> 42460 | D28: ='Data Sheet'!C$16 -> 42825 | E28: ='Data Sheet'!D$16 -> 43190 | F28: ='Data Sheet'!E$16 -> 43555 | G28: ='Data Sheet'!F$16 -> 43921 | H28: ='Data Sheet'!G$16 -> 44286 | I28: ='Data Sheet'!H$16 -> 44651 | J28: ='Data Sheet'!I$16 -> 45016 | ... L28: ='Data Sheet'!K$16 -> 45747
B30: Total Liabilities | C30: ='Data Sheet'!B61/'Data Sheet'!B$61 -> 1 | D30: ='Data Sheet'!C61/'Data Sheet'!C$61 -> 1 | E30: ='Data Sheet'!D61/'Data Sheet'!D$61 -> 1 | F30: ='Data Sheet'!E61/'Data Sheet'!E$61 -> 1 | G30: ='Data Sheet'!F61/'Data Sheet'!F$61 -> 1 | H30: ='Data Sheet'!G61/'Data Sheet'!G$61 -> 1 | I30: ='Data Sheet'!H61/'Data Sheet'!H$61 -> 1 | J30: ='Data Sheet'!I61/'Data Sheet'!I$61 -> 1 | ... L30: ='Data Sheet'!K61/'Data Sheet'!K$61 -> 1
B31: ='Data Sheet'!A57 -> Equity Share Capital | C31: ='Data Sheet'!B57/'Data Sheet'!B$61 -> 0.015579847 | D31: ='Data Sheet'!C57/'Data Sheet'!C$61 -> 0.021731243 | E31: ='Data Sheet'!D57/'Data Sheet'!D$61 -> 0.018997716 | F31: ='Data Sheet'!E57/'Data Sheet'!E$61 -> 0.017087767 | G31: ='Data Sheet'!F57/'Data Sheet'!F$61 -> 0.015899729 | H31: ='Data Sheet'!G57/'Data Sheet'!G$61 -> 0.016687464 | I31: ='Data Sheet'!H57/'Data Sheet'!H$61 -> 0.015963647 | J31: ='Data Sheet'!I57/'Data Sheet'!I$61 -> 0.014479624 | ... L31: ='Data Sheet'!K57/'Data Sheet'!K$61 -> 0.014220132
B32: ='Data Sheet'!A58 -> Reserves | C32: ='Data Sheet'!B58/'Data Sheet'!B$61 -> 0.8107205 | D32: ='Data Sheet'!C58/'Data Sheet'!C$61 -> 0.80857868 | E32: ='Data Sheet'!D58/'Data Sheet'!D$61 -> 0.79839629 | F32: ='Data Sheet'!E58/'Data Sheet'!E$61 -> 0.80730116 | G32: ='Data Sheet'!F58/'Data Sheet'!F$61 -> 0.8283976 | H32: ='Data Sheet'!G58/'Data Sheet'!G$61 -> 0.80146219 | I32: ='Data Sheet'!H58/'Data Sheet'!H$61 -> 0.79308804 | J32: ='Data Sheet'!I58/'Data Sheet'!I$61 -> 0.791235 | ... L32: ='Data Sheet'!K58/'Data Sheet'!K$61 -> 0.78155148
B33: ='Data Sheet'!A59 -> Borrowings | C33: ='Data Sheet'!B59/'Data Sheet'!B$61 -> 0.0016220296 | D33: ='Data Sheet'!C59/'Data Sheet'!C$61 -> 0.00081791367 | E33: ='Data Sheet'!D59/'Data Sheet'!D$61 -> 0.00055914552 | F33: ='Data Sheet'!E59/'Data Sheet'!E$61 -> 0.00018734569 | G33: ='Data Sheet'!F59/'Data Sheet'!F$61 -> 0.0035887635 | H33: ='Data Sheet'!G59/'Data Sheet'!G$61 -> 0.0036717355 | I33: ='Data Sheet'!H59/'Data Sheet'!H$61 -> 0.0032312547 | J33: ='Data Sheet'!I59/'Data Sheet'!I$61 -> 0.0035656132 | ... L33: ='Data Sheet'!K59/'Data Sheet'!K$61 -> 0.0032333099
B34: ='Data Sheet'!A60 -> Other Liabilities | C34: ='Data Sheet'!B60/'Data Sheet'!B$61 -> 0.17207763 | D34: ='Data Sheet'!C60/'Data Sheet'!C$61 -> 0.16887216 | E34: ='Data Sheet'!D60/'Data Sheet'!D$61 -> 0.18204685 | F34: ='Data Sheet'!E60/'Data Sheet'!E$61 -> 0.17542373 | G34: ='Data Sheet'!F60/'Data Sheet'!F$61 -> 0.1521139 | H34: ='Data Sheet'!G60/'Data Sheet'!G$61 -> 0.17817861 | I34: ='Data Sheet'!H60/'Data Sheet'!H$61 -> 0.18771706 | J34: ='Data Sheet'!I60/'Data Sheet'!I$61 -> 0.19071976 | ... L34: ='Data Sheet'!K60/'Data Sheet'!K$61 -> 0.20099508
B36: Total Assets | C36: ='Data Sheet'!B66/'Data Sheet'!B$66 -> 1 | D36: ='Data Sheet'!C66/'Data Sheet'!C$66 -> 1 | E36: ='Data Sheet'!D66/'Data Sheet'!D$66 -> 1 | F36: ='Data Sheet'!E66/'Data Sheet'!E$66 -> 1 | G36: ='Data Sheet'!F66/'Data Sheet'!F$66 -> 1 | H36: ='Data Sheet'!G66/'Data Sheet'!G$66 -> 1 | I36: ='Data Sheet'!H66/'Data Sheet'!H$66 -> 1 | J36: ='Data Sheet'!I66/'Data Sheet'!I$66 -> 1 | ... L36: ='Data Sheet'!K66/'Data Sheet'!K$66 -> 1
B37: ='Data Sheet'!A62 -> Net Block | C37: ='Data Sheet'!B62/'Data Sheet'!B$66 -> 0.29247315 | D37: ='Data Sheet'!C62/'Data Sheet'!C$66 -> 0.2843284 | E37: ='Data Sheet'!D62/'Data Sheet'!D$66 -> 0.25721877 | F37: ='Data Sheet'!E62/'Data Sheet'!E$66 -> 0.27006481 | G37: ='Data Sheet'!F62/'Data Sheet'!F$66 -> 0.28085797 | H37: ='Data Sheet'!G62/'Data Sheet'!G$66 -> 0.31586551 | I37: ='Data Sheet'!H62/'Data Sheet'!H$66 -> 0.31389688 | J37: ='Data Sheet'!I62/'Data Sheet'!I$66 -> 0.30118817 | ... L37: ='Data Sheet'!K62/'Data Sheet'!K$66 -> 0.24947928
B38: ='Data Sheet'!A63 -> Capital Work in Progress | C38: ='Data Sheet'!B63/'Data Sheet'!B$66 -> 0.049557669 | D38: ='Data Sheet'!C63/'Data Sheet'!C$66 -> 0.066726335 | E38: ='Data Sheet'!D63/'Data Sheet'!D$66 -> 0.085744934 | F38: ='Data Sheet'!E63/'Data Sheet'!E$66 -> 0.057659261 | G38: ='Data Sheet'!F63/'Data Sheet'!F$66 -> 0.042121697 | H38: ='Data Sheet'!G63/'Data Sheet'!G$66 -> 0.054382439 | I38: ='Data Sheet'!H63/'Data Sheet'!H$66 -> 0.04178376 | J38: ='Data Sheet'!I63/'Data Sheet'!I$66 -> 0.03499087 | ... L38: ='Data Sheet'!K63/'Data Sheet'!K$66 -> 0.012396324
B39: ='Data Sheet'!A64 -> Investments | C39: ='Data Sheet'!B64/'Data Sheet'!B$66 -> 0.22744018 | D39: ='Data Sheet'!C64/'Data Sheet'!C$66 -> 0.3145243 | E39: ='Data Sheet'!D64/'Data Sheet'!D$66 -> 0.3432839 | F39: ='Data Sheet'!E64/'Data Sheet'!E$66 -> 0.34909151 | G39: ='Data Sheet'!F64/'Data Sheet'!F$66 -> 0.37075504 | H39: ='Data Sheet'!G64/'Data Sheet'!G$66 -> 0.33718294 | I39: ='Data Sheet'!H64/'Data Sheet'!H$66 -> 0.32179133 | J39: ='Data Sheet'!I64/'Data Sheet'!I$66 -> 0.34270874 | ... L39: ='Data Sheet'!K64/'Data Sheet'!K$66 -> 0.3945313
B40: ='Data Sheet'!A65 -> Other Assets | C40: =HistoricalFS!C63/'Data Sheet'!B$66 -> 0.10057474 | D40: =HistoricalFS!D63/'Data Sheet'!C$66 -> 0.09187718 | E40: =HistoricalFS!E63/'Data Sheet'!D$66 -> 0.11019074 | F40: =HistoricalFS!F63/'Data Sheet'!E$66 -> 0.099500495 | G40: =HistoricalFS!G63/'Data Sheet'!F$66 -> 0.064136617 | H40: =HistoricalFS!H63/'Data Sheet'!G$66 -> 0.054530891 | I40: =HistoricalFS!I63/'Data Sheet'!H$66 -> 0.089608376 | J40: =HistoricalFS!J63/'Data Sheet'!I$66 -> 0.092668776 | ... L40: =HistoricalFS!L63/'Data Sheet'!K$66 -> 0.066674432
B41: ='Data Sheet'!A67 -> Receivables | C41: ='Data Sheet'!B67/'Data Sheet'!B$66 -> 0.03711772 | D41: ='Data Sheet'!C67/'Data Sheet'!C$66 -> 0.044264121 | E41: ='Data Sheet'!D67/'Data Sheet'!D$66 -> 0.041753631 | F41: ='Data Sheet'!E67/'Data Sheet'!E$66 -> 0.056249428 | G41: ='Data Sheet'!F67/'Data Sheet'!F$66 -> 0.033145196 | H41: ='Data Sheet'!G67/'Data Sheet'!G$66 -> 0.033916408 | I41: ='Data Sheet'!H67/'Data Sheet'!H$66 -> 0.031891541 | J41: ='Data Sheet'!I67/'Data Sheet'!I$66 -> 0.034441768 | ... L41: ='Data Sheet'!K67/'Data Sheet'!K$66 -> 0.053630968
B42: ='Data Sheet'!A68 -> Inventory | C42: ='Data Sheet'!B68/'Data Sheet'!B$66 -> 0.17544753 | D42: ='Data Sheet'!C68/'Data Sheet'!C$66 -> 0.14519399 | E42: ='Data Sheet'!D68/'Data Sheet'!D$66 -> 0.11667166 | F42: ='Data Sheet'!E68/'Data Sheet'!E$66 -> 0.10955764 | G42: ='Data Sheet'!F68/'Data Sheet'!F$66 -> 0.11485246 | H42: ='Data Sheet'!G68/'Data Sheet'!G$66 -> 0.14095788 | I42: ='Data Sheet'!H68/'Data Sheet'!H$66 -> 0.14073459 | J42: ='Data Sheet'!I68/'Data Sheet'!I$66 -> 0.13714352 | ... L42: ='Data Sheet'!K68/'Data Sheet'!K$66 -> 0.17769409
B43: ='Data Sheet'!A69 -> Cash & Bank | C43: ='Data Sheet'!B69/'Data Sheet'!B$66 -> 0.11738902 | D43: ='Data Sheet'!C69/'Data Sheet'!C$66 -> 0.053085674 | E43: ='Data Sheet'!D69/'Data Sheet'!D$66 -> 0.045136368 | F43: ='Data Sheet'!E69/'Data Sheet'!E$66 -> 0.057876855 | G43: ='Data Sheet'!F69/'Data Sheet'!F$66 -> 0.094131023 | H43: ='Data Sheet'!G69/'Data Sheet'!G$66 -> 0.063163937 | I43: ='Data Sheet'!H69/'Data Sheet'!H$66 -> 0.060293523 | J43: ='Data Sheet'!I69/'Data Sheet'!I$66 -> 0.056858155 | ... L43: ='Data Sheet'!K69/'Data Sheet'!K$66 -> 0.045593601

Sheet Ratio Analysis
B2: ='Data Sheet'!B1 -> ITC LTD
B3: (ITC | BSE Code: 540376)
B4: =CONCATENATE("INR"," ", 'Data Sheet'!B8) -> INR 409.75
B5: 52 Week (High - INR 410.45 & Low - INR 401.90)
B7: ="Ratio Analysis - "&'Data Sheet'!B1 -> Ratio Analysis - ITC LTD
B8: Years | C8: ='Data Sheet'!B16 -> 42460 | D8: ='Data Sheet'!C16 -> 42825 | E8: ='Data Sheet'!D16 -> 43190 | F8: ='Data Sheet'!E16 -> 43555 | G8: ='Data Sheet'!F16 -> 43921 | H8: ='Data Sheet'!G16 -> 44286 | I8: ='Data Sheet'!H16 -> 44651 | J8: ='Data Sheet'!I16 -> 45016 | ... L8: ='Data Sheet'!K16 -> 45747 | M8: Trend | N8: Mean | O8: Median
B10: Sales Growth | D10: =IFERROR(HistoricalFS!D11,0) -> 0.09123012 | E10: =IFERROR(HistoricalFS!E11,0) -> 0.015931219 | F10: =IFERROR(HistoricalFS!F11,0) -> 0.11256063 | G10: =IFERROR(HistoricalFS!G11,0) -> 0.021682439 | H10: =IFERROR(HistoricalFS!H11,0) -> -0.0026372963 | I10: =IFERROR(HistoricalFS!I11,0) -> 0.23117498 | J10: =IFERROR(HistoricalFS!J11,0) -> 0.16942152 | K10: =IFERROR(HistoricalFS!K11,0) -> -0.042119724 | L10: =IFERROR(HistoricalFS!L11,0) -> 0.10880596 | N10: =IFERROR(AVERAGE(D10:L10),0) -> 0.078449983 | O10: =IFERROR(MEDIAN(D10:L10),0) -> 0.09123012
B11: EBITDA Growth | D11: =IFERROR(HistoricalFS!D22/HistoricalFS!C22-1,0) -> 0.064550848 | E11: =IFERROR(HistoricalFS!E22/HistoricalFS!D22-1,0) -> 0.067945268 | F11: =IFERROR(HistoricalFS!F22/HistoricalFS!E22-1,0) -> 0.12207796 | G11: =IFERROR(HistoricalFS!G22/HistoricalFS!F22-1,0) -> 0.043487783 | H11: =IFERROR(HistoricalFS!H22/HistoricalFS!G22-1,0) -> -0.1178047 | I11: =IFERROR(HistoricalFS!I22/HistoricalFS!H22-1,0) -> 0.20852129 | J11: =IFERROR(HistoricalFS!J22/HistoricalFS!I22-1,0) -> 0.24637895 | K11: =IFERROR(HistoricalFS!K22/HistoricalFS!J22-1,0) -> -0.020102893 | L11: =IFERROR(HistoricalFS!L22/HistoricalFS!K22-1,0) -> 0.025882649 | N11: =IFERROR(AVERAGE(D11:L11),0) -> 0.07121524 | O11: =IFERROR(MEDIAN(D11:L11),0) -> 0.064550848
B12: EBIT Growth | D12: =IFERROR(HistoricalFS!D31/HistoricalFS!C31-1,0) -> 0.064116562 | E12: =IFERROR(HistoricalFS!E31/HistoricalFS!D31-1,0) -> 0.067584614 | F12: =IFERROR(HistoricalFS!F31/HistoricalFS!E31-1,0) -> 0.12146247 | G12: =IFERROR(HistoricalFS!G31/HistoricalFS!F31-1,0) -> 0.032545193 | H12: =IFERROR(HistoricalFS!H31/HistoricalFS!G31-1,0) -> -0.12879189 | I12: =IFERROR(HistoricalFS!I31/HistoricalFS!H31-1,0) -> 0.22514477 | J12: =IFERROR(HistoricalFS!J31/HistoricalFS!I31-1,0) -> 0.26491869 | K12: =IFERROR(HistoricalFS!K31/HistoricalFS!J31-1,0) -> -0.0094483213 | L12: =IFERROR(HistoricalFS!L31/HistoricalFS!K31-1,0) -> 0.022123426 | N12: =IFERROR(AVERAGE(D12:L12),0) -> 0.073295057 | O12: =IFERROR(MEDIAN(D12:L12),0) -> 0.064116562
B13: EBT Growth | D13: =IFERROR(HistoricalFS!D34/HistoricalFS!C34-1,0) -> 0.066666617 | E13: =IFERROR(HistoricalFS!E34/HistoricalFS!D34-1,0) -> 0.06319243 | F13: =IFERROR(HistoricalFS!F34/HistoricalFS!E34-1,0) -> 0.12525825 | G13: =IFERROR(HistoricalFS!G34/HistoricalFS!F34-1,0) -> 0.032096655 | H13: =IFERROR(HistoricalFS!H34/HistoricalFS!G34-1,0) -> -0.12805801 | I13: =IFERROR(HistoricalFS!I34/HistoricalFS!H34-1,0) -> 0.22586292 | J13: =IFERROR(HistoricalFS!J34/HistoricalFS!I34-1,0) -> 0.26481845 | K13: =IFERROR(HistoricalFS!K34/HistoricalFS!J34-1,0) -> -0.0078559948 | L13: =IFERROR(HistoricalFS!L34/HistoricalFS!K34-1,0) -> 0.021908248 | N13: =IFERROR(AVERAGE(D13:L13),0) -> 0.073765507 | O13: =IFERROR(MEDIAN(D13:L13),0) -> 0.06319243
B14: Net Profit Growth | D14: =IFERROR(HistoricalFS!D40/HistoricalFS!C40-1,0) -> 0.087412304 | E14: =IFERROR(HistoricalFS!E40/HistoricalFS!D40-1,0) -> 0.061279334 | F14: =IFERROR(HistoricalFS!F40/HistoricalFS!E40-1,0) -> 0.16239178 | G14: =IFERROR(HistoricalFS!G40/HistoricalFS!F40-1,0) -> 0.225002 | H14: =IFERROR(HistoricalFS!H40/HistoricalFS!G40-1,0) -> -0.1798442 | I14: =IFERROR(HistoricalFS!I40/HistoricalFS!H40-1,0) -> 0.25795836 | J14: =IFERROR(HistoricalFS!J40/HistoricalFS!I40-1,0) -> 0.27849303 | K14: =IFERROR(HistoricalFS!K40/HistoricalFS!J40-1,0) -> 0.0024069168 | L14: =IFERROR(HistoricalFS!L40/HistoricalFS!K40-1,0) -> -0.0093743668 | N14: =IFERROR(AVERAGE(D14:L14),0) -> 0.098413907 | O14: =IFERROR(MEDIAN(D14:L14),0) -> 0.087412304
B15: Dividend Growth | D15: =IFERROR(HistoricalFS!D48/HistoricalFS!C48-1,0) -> -0.16176398 | E15: =IFERROR(HistoricalFS!E48/HistoricalFS!D48-1,0) -> 0.084208811 | F15: =IFERROR(HistoricalFS!F48/HistoricalFS!E48-1,0) -> 0.11650645 | G15: =IFERROR(HistoricalFS!G48/HistoricalFS!F48-1,0) -> 0.76521571 | H15: =IFERROR(HistoricalFS!H48/HistoricalFS!G48-1,0) -> 0.059113555 | I15: =IFERROR(HistoricalFS!I48/HistoricalFS!H48-1,0) -> 0.069767819 | J15: =IFERROR(HistoricalFS!J48/HistoricalFS!I48-1,0) -> 0.34782561 | K15: =IFERROR(HistoricalFS!K48/HistoricalFS!J48-1,0) -> -0.11290335 | L15: =IFERROR(HistoricalFS!L48/HistoricalFS!K48-1,0) -> 0.043636312 | N15: =IFERROR(AVERAGE(D15:L15),0) -> 0.13462299 | O15: =IFERROR(MEDIAN(D15:L15),0) -> 0.069767819
B17: Gross Margin | C17: =IFERROR(HistoricalFS!C17,0) -> 0.51105095 | D17: =IFERROR(HistoricalFS!D17,0) -> 0.48678158 | E17: =IFERROR(HistoricalFS!E17,0) -> 0.49440654 | F17: =IFERROR(HistoricalFS!F17,0) -> 0.49904509 | G17: =IFERROR(HistoricalFS!G17,0) -> 0.50735912 | H17: =IFERROR(HistoricalFS!H17,0) -> 0.45426509 | I17: =IFERROR(HistoricalFS!I17,0) -> 0.43848102 | J17: =IFERROR(HistoricalFS!J17,0) -> 0.45991746 | ... L17: =IFERROR(HistoricalFS!L17,0) -> 0.44945073 | N17: =IFERROR(AVERAGE(C17:L17),0) -> 0.47757322 | O17: =IFERROR(MEDIAN(C17:L17),0) -> 0.48087812
B18: EBITA Margin | C18: =IFERROR(HistoricalFS!C23,0) -> 0.370776 | D18: =IFERROR(HistoricalFS!D23,0) -> 0.36171097 | E18: =IFERROR(HistoricalFS!E23,0) -> 0.38022999 | F18: =IFERROR(HistoricalFS!F23,0) -> 0.38348265 | G18: =IFERROR(HistoricalFS!G23,0) -> 0.39166716 | H18: =IFERROR(HistoricalFS!H23,0) -> 0.34644059 | I18: =IFERROR(HistoricalFS!I23,0) -> 0.34006606 | J18: =IFERROR(HistoricalFS!J23,0) -> 0.36244517 | ... L18: =IFERROR(HistoricalFS!L23,0) -> 0.34304706 | N18: =IFERROR(AVERAGE(C18:L18),0) -> 0.36506416 | O18: =IFERROR(MEDIAN(C18:L18),0) -> 0.36661056
B19: EBIT Margin | C19: =IFERROR(HistoricalFS!C32,0) -> 0.34328576 | D19: =IFERROR(HistoricalFS!D32,0) -> 0.33475622 | E19: =IFERROR(HistoricalFS!E32,0) -> 0.35177636 | F19: =IFERROR(HistoricalFS!F32,0) -> 0.354591 | G19: =IFERROR(HistoricalFS!G32,0) -> 0.35836109 | H19: =IFERROR(HistoricalFS!H32,0) -> 0.31303265 | I19: =IFERROR(HistoricalFS!I32,0) -> 0.31149944 | J19: =IFERROR(HistoricalFS!J32,0) -> 0.33693707 | ... L19: =IFERROR(HistoricalFS!L32,0) -> 0.32119035 | N19: =IFERROR(AVERAGE(C19:L19),0) -> 0.33738593 | O19: =IFERROR(MEDIAN(C19:L19),0) -> 0.34011142
B20: EBT Margin | C20: =IFERROR(HistoricalFS!C35,0) -> 0.34129225 | D20: =IFERROR(HistoricalFS!D35,0) -> 0.33360979 | E20: =IFERROR(HistoricalFS!E35,0) -> 0.34912935 | F20: =IFERROR(HistoricalFS!F35,0) -> 0.35311395 | G20: =IFERROR(HistoricalFS!G35,0) -> 0.35671331 | H20: =IFERROR(HistoricalFS!H35,0) -> 0.31185577 | I20: =IFERROR(HistoricalFS!I35,0) -> 0.31051023 | J20: =IFERROR(HistoricalFS!J35,0) -> 0.33584046 | ... L20: =IFERROR(HistoricalFS!L35,0) -> 0.32059213 | N20: =IFERROR(AVERAGE(C20:L20),0) -> 0.33605108 | O20: =IFERROR(MEDIAN(C20:L20),0) -> 0.33856636
B21: Net Profit Margin | C21: =IFERROR(HistoricalFS!C41,0) -> 0.20457567 | D21: =IFERROR(HistoricalFS!D41,0) -> 0.20385993 | E21: =IFERROR(HistoricalFS!E41,0) -> 0.21295963 | F21: =IFERROR(HistoricalFS!F41,0) -> 0.222498 | G21: =IFERROR(HistoricalFS!G41,0) -> 0.26677614 | H21: =IFERROR(HistoricalFS!H41,0) -> 0.21937656 | I21: =IFERROR(HistoricalFS!I41,0) -> 0.22414895 | J21: =IFERROR(HistoricalFS!J41,0) -> 0.24505524 | ... L21: =IFERROR(HistoricalFS!L41,0) -> 0.22911358 | N21: =IFERROR(AVERAGE(C21:L21),0) -> 0.22848102 | O21: =IFERROR(MEDIAN(C21:L21),0) -> 0.22332348
B23: Sales Expenses % of sales | C23: =IFERROR(HistoricalFS!C20,0) -> 0.14027495 | D23: =IFERROR(HistoricalFS!D20,0) -> 0.12507061 | E23: =IFERROR(HistoricalFS!E20,0) -> 0.11417655 | F23: =IFERROR(HistoricalFS!F20,0) -> 0.11556244 | G23: =IFERROR(HistoricalFS!G20,0) -> 0.11569196 | H23: =IFERROR(HistoricalFS!H20,0) -> 0.1078245 | I23: =IFERROR(HistoricalFS!I20,0) -> 0.09841496 | J23: =IFERROR(HistoricalFS!J20,0) -> 0.097472286 | ... L23: =IFERROR(HistoricalFS!L20,0) -> 0.10640367 | N23: =IFERROR(AVERAGE(C23:L23),0) -> 0.11250906 | O23: =IFERROR(MEDIAN(C23:L23),0) -> 0.11100053
B24: Depriciation % of sales | C24: =IFERROR(HistoricalFS!C29,0) -> 0.027490234 | D24: =IFERROR(HistoricalFS!D29,0) -> 0.026954751 | E24: =IFERROR(HistoricalFS!E29,0) -> 0.028453629 | F24: =IFERROR(HistoricalFS!F29,0) -> 0.028891645 | G24: =IFERROR(HistoricalFS!G29,0) -> 0.033306066 | H24: =IFERROR(HistoricalFS!H29,0) -> 0.033407941 | I24: =IFERROR(HistoricalFS!I29,0) -> 0.028566628 | J24: =IFERROR(HistoricalFS!J29,0) -> 0.025508104 | ... L24: =IFERROR(HistoricalFS!L29,0) -> 0.021856705 | N24: =IFERROR(AVERAGE(C24:L24),0) -> 0.027678233 | O24: =IFERROR(MEDIAN(C24:L24),0) -> 0.027971931
B25: Operating Income % of sales | C25: =C19 -> 0.34328576 | D25: =D19 -> 0.33475622 | E25: =E19 -> 0.35177636 | F25: =F19 -> 0.354591 | G25: =G19 -> 0.35836109 | H25: =H19 -> 0.31303265 | I25: =I19 -> 0.31149944 | J25: =J19 -> 0.33693707 | ... L25: =L19 -> 0.32119035 | N25: =IFERROR(AVERAGE(C25:L25),0) -> 0.33738593 | O25: =IFERROR(MEDIAN(C25:L25),0) -> 0.34011142
B27: Return on Capital Employed (%) | C27: =IFERROR(HistoricalFS!C31/SUM(HistoricalFS!C54:C56),0) -> 0.31461767 | D27: =IFERROR(HistoricalFS!D31/SUM(HistoricalFS!D54:D56),0) -> 0.30816048 | E27: =IFERROR(HistoricalFS!E31/SUM(HistoricalFS!E54:E56),0) -> 0.29087469 | F27: =IFERROR(HistoricalFS!F31/SUM(HistoricalFS!F54:F56),0) -> 0.28976384 | G27: =IFERROR(HistoricalFS!G31/SUM(HistoricalFS!G54:G56),0) -> 0.26999906 | H27: =IFERROR(HistoricalFS!H31/SUM(HistoricalFS!H54:H56),0) -> 0.25436581 | I27: =IFERROR(HistoricalFS!I31/SUM(HistoricalFS!I54:I56),0) -> 0.30126365 | J27: =IFERROR(HistoricalFS!J31/SUM(HistoricalFS!J54:J56),0) -> 0.3440081 | ... L27: =IFERROR(HistoricalFS!L31/SUM(HistoricalFS!L54:L56),0) -> 0.34406984 | N27: =IFERROR(AVERAGE(C27:L27),0) -> 0.30335159 | O27: =IFERROR(MEDIAN(C27:L27),0) -> 0.30471206
B28: Retained Earnings (%) | C28: =IFERROR(HistoricalFS!C51,0) -> 0.14687786 | D28: =IFERROR(HistoricalFS!D51,0) -> 0.33819421 | E28: =IFERROR(HistoricalFS!E51,0) -> 0.3207286 | F28: =IFERROR(HistoricalFS!F51,0) -> 0.34463984 | G28: =IFERROR(HistoricalFS!G51,0) -> 0.053044068 | H28: =IFERROR(HistoricalFS!H51,0) -> 0 | I28: =IFERROR(HistoricalFS!I51,0) -> 0 | J28: =IFERROR(HistoricalFS!J51,0) -> 0 | ... L28: =IFERROR(HistoricalFS!L51,0) -> 0 | N28: =IFERROR(AVERAGE(C28:L28),0) -> 0.12180906 | O28: =IFERROR(MEDIAN(C28:L28),0) -> 0.03382504
B29: Return on Equity (%) | C29: =IFERROR(HistoricalFS!C40/SUM(HistoricalFS!C54:C55),0) -> 0.18785942 | D29: =IFERROR(HistoricalFS!D40/SUM(HistoricalFS!D54:D55),0) -> 0.18784852 | E29: =IFERROR(HistoricalFS!E40/SUM(HistoricalFS!E54:E55),0) -> 0.17621121 | F29: =IFERROR(HistoricalFS!F40/SUM(HistoricalFS!F54:F55),0) -> 0.18186171 | G29: =IFERROR(HistoricalFS!G40/SUM(HistoricalFS!G54:G55),0) -> 0.2018508 | H29: =IFERROR(HistoricalFS!H40/SUM(HistoricalFS!H54:H55),0) -> 0.17906224 | I29: =IFERROR(HistoricalFS!I40/SUM(HistoricalFS!I54:I55),0) -> 0.21764928 | J29: =IFERROR(HistoricalFS!J40/SUM(HistoricalFS!J54:J55),0) -> 0.25130525 | ... L29: =IFERROR(HistoricalFS!L40/SUM(HistoricalFS!L54:L55),0) -> 0.24643135 | N29: =IFERROR(AVERAGE(C29:L29),0) -> 0.20638955 | O29: =IFERROR(MEDIAN(C29:L29),0) -> 0.19485511
B30: Self Sustained Growth Rate (%) | C30: =IFERROR(C28*C29,0) -> 0.027592391 | D30: =IFERROR(D28*D29,0) -> 0.063529279 | E30: =IFERROR(E28*E29,0) -> 0.056515974 | F30: =IFERROR(F28*F29,0) -> 0.062676792 | G30: =IFERROR(G28*G29,0) -> 0.010706988 | H30: =IFERROR(H28*H29,0) -> 0 | I30: =IFERROR(I28*I29,0) -> 0 | J30: =IFERROR(J28*J29,0) -> 0 | ... L30: =IFERROR(L28*L29,0) -> 0 | N30: =IFERROR(AVERAGE(C30:L30),0) -> 0.022443654 | O30: =IFERROR(MEDIAN(C30:L30),0) -> 0.0070610516
B31: Interest Coverage Ratio | C31: =IFERROR(HistoricalFS!C31/HistoricalFS!C25,0) -> 172.20133 | D31: =IFERROR(HistoricalFS!D31/HistoricalFS!D25,0) -> 291.99918 | E31: =IFERROR(HistoricalFS!E31/HistoricalFS!E25,0) -> 132.89549 | F31: =IFERROR(HistoricalFS!F31/HistoricalFS!F25,0) -> 240.06695 | G31: =IFERROR(HistoricalFS!G31/HistoricalFS!G25,0) -> 217.48132 | H31: =IFERROR(HistoricalFS!H31/HistoricalFS!H25,0) -> 265.98568 | I31: =IFERROR(HistoricalFS!I31/HistoricalFS!I25,0) -> 314.89815 | J31: =IFERROR(HistoricalFS!J31/HistoricalFS!J25,0) -> 307.25537 | ... L31: =IFERROR(HistoricalFS!L31/HistoricalFS!L25,0) -> 536.90923 | N31: =IFERROR(AVERAGE(C31:L31),0) -> 308.48955 | O31: =IFERROR(MEDIAN(C31:L31),0) -> 278.99243
B33: Debtor Turnover Ratio | C33: =IFERROR(HistoricalFS!C10/HistoricalFS!C66,0) -> 20.442577 | D33: =IFERROR(HistoricalFS!D10/HistoricalFS!D66,0) -> 17.284797 | E33: =IFERROR(HistoricalFS!E10/HistoricalFS!E66,0) -> 16.19845 | F33: =IFERROR(HistoricalFS!F10/HistoricalFS!F66,0) -> 11.979238 | G33: =IFERROR(HistoricalFS!G10/HistoricalFS!G66,0) -> 19.273399 | H33: =IFERROR(HistoricalFS!H10/HistoricalFS!H66,0) -> 19.689591 | I33: =IFERROR(HistoricalFS!I10/HistoricalFS!I66,0) -> 24.633226 | J33: =IFERROR(HistoricalFS!J10/HistoricalFS!J66,0) -> 23.990173 | ... L33: =IFERROR(HistoricalFS!L10/HistoricalFS!L66,0) -> 15.959451 | N33: =IFERROR(AVERAGE(C33:L33),0) -> 18.632497 | O33: =IFERROR(MEDIAN(C33:L33),0) -> 18.279098
B34: Creditor Turnover Ratio | C34: =IFERROR(HistoricalFS!C10/HistoricalFS!C57,0) -> 4.4095324 | D34: =IFERROR(HistoricalFS!D10/HistoricalFS!D57,0) -> 4.5306245 | E34: =IFERROR(HistoricalFS!E10/HistoricalFS!E57,0) -> 3.7152199 | F34: =IFERROR(HistoricalFS!F10/HistoricalFS!F57,0) -> 3.8411297 | G34: =IFERROR(HistoricalFS!G10/HistoricalFS!G57,0) -> 4.1996201 | H34: =IFERROR(HistoricalFS!H10/HistoricalFS!H57,0) -> 3.7479256 | I34: =IFERROR(HistoricalFS!I10/HistoricalFS!I57,0) -> 4.1849768 | J34: =IFERROR(HistoricalFS!J10/HistoricalFS!J57,0) -> 4.3323459 | ... L34: =IFERROR(HistoricalFS!L10/HistoricalFS!L57,0) -> 4.2584165 | N34: =IFERROR(AVERAGE(C34:L34),0) -> 4.1229104 | O34: =IFERROR(MEDIAN(C34:L34),0) -> 4.1922984
B35: Inventory Turnover | C35: =IFERROR(HistoricalFS!C10/HistoricalFS!C67,0) -> 4.3248364 | D35: =IFERROR(HistoricalFS!D10/HistoricalFS!D67,0) -> 5.2694767 | E35: =IFERROR(HistoricalFS!E10/HistoricalFS!E67,0) -> 5.7969871 | F35: =IFERROR(HistoricalFS!F10/HistoricalFS!F67,0) -> 6.1504181 | G35: =IFERROR(HistoricalFS!G10/HistoricalFS!G67,0) -> 5.5620976 | H35: =IFERROR(HistoricalFS!H10/HistoricalFS!H67,0) -> 4.737587 | I35: =IFERROR(HistoricalFS!I10/HistoricalFS!I67,0) -> 5.5820787 | J35: =IFERROR(HistoricalFS!J10/HistoricalFS!J67,0) -> 6.0248123 | ... L35: =IFERROR(HistoricalFS!L10/HistoricalFS!L67,0) -> 4.8168218 | N35: =IFERROR(AVERAGE(C35:L35),0) -> 5.3064983 | O35: =IFERROR(MEDIAN(C35:L35),0) -> 5.4157872
B36: Fixed Asset Turnover | C36: =IFERROR(HistoricalFS!C10/HistoricalFS!C60,0) -> 2.5943642 | D36: =IFERROR(HistoricalFS!D10/HistoricalFS!D60,0) -> 2.6908896 | E36: =IFERROR(HistoricalFS!E10/HistoricalFS!E60,0) -> 2.6294508 | F36: =IFERROR(HistoricalFS!F10/HistoricalFS!F60,0) -> 2.4950504 | G36: =IFERROR(HistoricalFS!G10/HistoricalFS!G60,0) -> 2.2745326 | H36: =IFERROR(HistoricalFS!H10/HistoricalFS!H60,0) -> 2.1141916 | I36: =IFERROR(HistoricalFS!I10/HistoricalFS!I60,0) -> 2.5027058 | J36: =IFERROR(HistoricalFS!J10/HistoricalFS!J60,0) -> 2.743348 | ... L36: =IFERROR(HistoricalFS!L10/HistoricalFS!L60,0) -> 3.4308292 | N36: =IFERROR(AVERAGE(C36:L36),0) -> 2.5917181 | O36: =IFERROR(MEDIAN(C36:L36),0) -> 2.548535
B37: Capital Turnover Ratio | C37: =IFERROR(HistoricalFS!C10/SUM(HistoricalFS!C54:C55),0) -> 0.91828821 | D37: =IFERROR(HistoricalFS!D10/SUM(HistoricalFS!D54:D55),0) -> 0.92145874 | E37: =IFERROR(HistoricalFS!E10/SUM(HistoricalFS!E54:E55),0) -> 0.82743952 | F37: =IFERROR(HistoricalFS!F10/SUM(HistoricalFS!F54:F55),0) -> 0.81736336 | G37: =IFERROR(HistoricalFS!G10/SUM(HistoricalFS!G54:G55),0) -> 0.7566299 | H37: =IFERROR(HistoricalFS!H10/SUM(HistoricalFS!H54:H55),0) -> 0.81623233 | I37: =IFERROR(HistoricalFS!I10/SUM(HistoricalFS!I54:I55),0) -> 0.97100291 | J37: =IFERROR(HistoricalFS!J10/SUM(HistoricalFS!J54:J55),0) -> 1.0255045 | ... L37: =IFERROR(HistoricalFS!L10/SUM(HistoricalFS!L54:L55),0) -> 1.075586 | N37: =IFERROR(AVERAGE(C37:L37),0) -> 0.90412579 | O37: =IFERROR(MEDIAN(C37:L37),0) -> 0.91502033
B39: Debtor Days | C39: =IFERROR(365/C33,0) -> 17.854892 | D39: =IFERROR(365/D33,0) -> 21.116823 | E39: =IFERROR(365/E33,0) -> 22.53302 | F39: =IFERROR(365/F33,0) -> 30.469383 | G39: =IFERROR(365/G33,0) -> 18.938019 | H39: =IFERROR(365/H33,0) -> 18.537714 | I39: =IFERROR(365/I33,0) -> 14.817385 | J39: =IFERROR(365/J33,0) -> 15.214563 | ... L39: =IFERROR(365/L33,0) -> 22.870462 | N39: =IFERROR(AVERAGE(C39:L39),0) -> 20.398309 | O39: =IFERROR(MEDIAN(C39:L39),0) -> 20.027421
B40: Payable Days | C40: =IFERROR(365/C34,0) -> 82.775217 | D40: =IFERROR(365/D34,0) -> 80.562845 | E40: =IFERROR(365/E34,0) -> 98.24452 | F40: =IFERROR(365/F34,0) -> 95.024128 | G40: =IFERROR(365/G34,0) -> 86.912624 | H40: =IFERROR(365/H34,0) -> 97.387204 | I40: =IFERROR(365/I34,0) -> 87.216733 | J40: =IFERROR(365/J34,0) -> 84.249966 | ... L40: =IFERROR(365/L34,0) -> 85.712611 | N40: =IFERROR(AVERAGE(C40:L40),0) -> 88.912391 | O40: =IFERROR(MEDIAN(C40:L40),0) -> 87.064678
B41: Inventory Days | C41: =IFERROR(365/C35,0) -> 84.396256 | D41: =IFERROR(365/D35,0) -> 69.26684 | E41: =IFERROR(365/E35,0) -> 62.963742 | F41: =IFERROR(365/F35,0) -> 59.345559 | G41: =IFERROR(365/G35,0) -> 65.622725 | H41: =IFERROR(365/H35,0) -> 77.04344 | I41: =IFERROR(365/I35,0) -> 65.387828 | J41: =IFERROR(365/J35,0) -> 60.5828 | ... L41: =IFERROR(365/L35,0) -> 75.776106 | N41: =IFERROR(AVERAGE(C41:L41),0) -> 69.642907 | O41: =IFERROR(MEDIAN(C41:L41),0) -> 67.444782
B42: Cash Conversion Cycle (in days) | C42: =IFERROR(SUM(C39,C41)-C40,0) -> 19.47593 | D42: =IFERROR(SUM(D39,D41)-D40,0) -> 9.8208176 | E42: =IFERROR(SUM(E39,E41)-E40,0) -> -12.747757 | F42: =IFERROR(SUM(F39,F41)-F40,0) -> -5.2091857 | G42: =IFERROR(SUM(G39,G41)-G40,0) -> -2.3518801 | H42: =IFERROR(SUM(H39,H41)-H40,0) -> -1.8060507 | I42: =IFERROR(SUM(I39,I41)-I40,0) -> -7.0115199 | J42: =IFERROR(SUM(J39,J41)-J40,0) -> -8.4526036 | ... L42: =IFERROR(SUM(L39,L41)-L40,0) -> 12.933956 | N42: =IFERROR(AVERAGE(C42:L42),0) -> 1.1288252 | O42: =IFERROR(MEDIAN(C42:L42),0) -> -2.0789654
B44: CFO/Sales | C44: =IFERROR(HistoricalFS!C77/HistoricalFS!C10,0) -> 0.2500259 | D44: =IFERROR(HistoricalFS!D77/HistoricalFS!D10,0) -> 0.24848974 | E44: =IFERROR(HistoricalFS!E77/HistoricalFS!E10,0) -> 0.3031006 | F44: =IFERROR(HistoricalFS!F77/HistoricalFS!F10,0) -> 0.26031277 | G44: =IFERROR(HistoricalFS!G77/HistoricalFS!G10,0) -> 0.2974356 | H44: =IFERROR(HistoricalFS!H77/HistoricalFS!H10,0) -> 0.25431625 | I44: =IFERROR(HistoricalFS!I77/HistoricalFS!I10,0) -> 0.26013076 | J44: =IFERROR(HistoricalFS!J77/HistoricalFS!J10,0) -> 0.26618455 | ... L44: =IFERROR(HistoricalFS!L77/HistoricalFS!L10,0) -> 0.2340183 | N44: =IFERROR(AVERAGE(C44:L44),0) -> 0.26268979 | O44: =IFERROR(MEDIAN(C44:L44),0) -> 0.2572235
B45: CFO/Total Assets | C45: =IFERROR(HistoricalFS!C77/HistoricalFS!C71,0) -> 0.18971512 | D45: =IFERROR(HistoricalFS!D77/HistoricalFS!D71,0) -> 0.19011859 | E45: =IFERROR(HistoricalFS!E77/HistoricalFS!E71,0) -> 0.20500031 | F45: =IFERROR(HistoricalFS!F77/HistoricalFS!F71,0) -> 0.17540533 | G45: =IFERROR(HistoricalFS!G77/HistoricalFS!G71,0) -> 0.19000799 | H45: =IFERROR(HistoricalFS!H77/HistoricalFS!H71,0) -> 0.16983244 | I45: =IFERROR(HistoricalFS!I77/HistoricalFS!I71,0) -> 0.20435652 | J45: =IFERROR(HistoricalFS!J77/HistoricalFS!J71,0) -> 0.2199387 | ... L45: =IFERROR(HistoricalFS!L77/HistoricalFS!L71,0) -> 0.20030113 | N45: =IFERROR(AVERAGE(C45:L45),0) -> 0.19319036 | O45: =IFERROR(MEDIAN(C45:L45),0) -> 0.19006329
B46: CFO/Total Debt | C46: =IFERROR(HistoricalFS!C77/HistoricalFS!C56,0) -> 116.96157 | D46: =IFERROR(HistoricalFS!D77/HistoricalFS!D56,0) -> 232.44335 | E46: =IFERROR(HistoricalFS!E77/HistoricalFS!E56,0) -> 366.6314 | F46: =IFERROR(HistoricalFS!F77/HistoricalFS!F56,0) -> 936.26562 | G46: =IFERROR(HistoricalFS!G77/HistoricalFS!G56,0) -> 52.945251 | H46: =IFERROR(HistoricalFS!H77/HistoricalFS!H56,0) -> 46.253997 | I46: =IFERROR(HistoricalFS!I77/HistoricalFS!I56,0) -> 63.243706 | J46: =IFERROR(HistoricalFS!J77/HistoricalFS!J56,0) -> 61.683277 | ... L46: =IFERROR(HistoricalFS!L77/HistoricalFS!L56,0) -> 61.949251 | N46: =IFERROR(AVERAGE(C46:L46),0) -> 199.4993 | O46: =IFERROR(MEDIAN(C46:L46),0) -> 62.596479

Sheet WACC
B2: ='Data Sheet'!B1 -> ITC LTD
B3: (ITC | BSE Code: 540376)
B4: =CONCATENATE("INR"," ", 'Data Sheet'!B8) -> INR 409.75
B5: 52 Week (High - INR 410.45 & Low - INR 401.90)
B6: Weighted Average Cost of Capital
B7: Peers comms
I8: Debt / | J8: Debt / | K8: Levered 2 | L8: Unlevered 3
B9: Name of the comp | C9: Ticker | E9: Country | F9: Total Debt | G9: Total Equity | H9: Tax rate 1 | I9: Equity | J9: Capital | K9: Beta | L9: Beta
B11: ='Comps Data'!C4 -> Hind. Unilever | C11: ='Comps Data'!D4 -> HINDUNILVR | E11: India | F11: ='Comps Data'!H4 -> 1648 | G11: ='Comps Data'!G4 -> 624946.61 | H11: 0.3 | I11: =F11/G11 -> 0.0026370253 | J11: =F11/SUM(G11,F11) -> 0.0026300897 | K11: 0.448 | L11: =K11/(1+(1-H11)*I11) -> 0.44717455
B12: ='Comps Data'!C3 -> ITC | C12: ='Comps Data'!D3 -> ITC | E12: India | F12: ='Comps Data'!H3 -> 284.54 | G12: ='Comps Data'!G3 -> 513281.53 | H12: 0.3 | I12: =F12/G12 -> 0.00055435464 | J12: =F12/SUM(G12,F12) -> 0.0005540475 | K12: 0.566 | L12: =K12/(1+(1-H12)*I12) -> 0.56578045
B13: ='Comps Data'!C5 -> Nestle India | C13: ='Comps Data'!D5 -> NESTLEIND | E13: India | F13: ='Comps Data'!H5 -> 1166.85 | G13: ='Comps Data'!G5 -> 222950.05 | H13: 0.3 | I13: =F13/G13 -> 0.0052336836 | J13: =F13/SUM(G13,F13) -> 0.0052064348 | K13: 0.702 | L13: =K13/(1+(1-H13)*I13) -> 0.69943756
B14: ='Comps Data'!C6 -> Varun Beverages | C14: ='Comps Data'!D6 -> VBL | E14: India | F14: ='Comps Data'!H6 -> 2138.25 | G14: ='Comps Data'!G6 -> 164754.13 | H14: 0.3 | I14: =F14/G14 -> 0.01297843 | J14: =F14/SUM(G14,F14) -> 0.012812149 | K14: 0.911 | L14: =K14/(1+(1-H14)*I14) -> 0.90279817
B15: ='Comps Data'!C7 -> Britannia Inds. | C15: ='Comps Data'!D7 -> BRITANNIA | E15: India | F15: ='Comps Data'!H7 -> 1246.51 | G15: ='Comps Data'!G7 -> 140300.16 | H15: 0.3 | I15: =F15/G15 -> 0.0088845943 | J15: =F15/SUM(G15,F15) -> 0.0088063534 | K15: 0.528 | L15: =K15/(1+(1-H15)*I15) -> 0.52473655
G17: Average | H17: =AVERAGE(H11:H15) -> 0.3 | I17: =AVERAGE(I11:I15) -> 0.0060576176 | J17: =AVERAGE(J11:J15) -> 0.0060018148 | K17: =AVERAGE(K11:K15) -> 0.631 | L17: =AVERAGE(L11:L15) -> 0.62798546
G18: Median | H18: =MEDIAN(H11:H15) -> 0.3 | I18: =MEDIAN(I11:I15) -> 0.0052336836 | J18: =MEDIAN(J11:J15) -> 0.0052064348 | K18: =MEDIAN(K11:K15) -> 0.566 | L18: =MEDIAN(L11:L15) -> 0.56578045
B20: Cost of Debt | H20: Cost of Equity
B22: Interest | F22: 216 | H22: Risk Free Rate | L22: 0.06402
B23: Pre-Tax Cost of Debt | F23: =F22/F11 -> 0.13106796 | H23: Market Risk Premium | L23: 0.06
B24: Tax Rate | F24: =H14 -> 0.3 | H24: Levered Beta 4 | L24: =L32 -> 0.56786414
B25: Post Tax Cost of Debt | F25: =F23*(1-F24) -> 0.091747573 | H25: Cost of Equity | L25: =L22+L23*L24 -> 0.098091848
B27: Capital Structure | H27: Levered Beta
E29: Current | F29: Target | H29: Comps Median Unlevered Beta | L29: =L18 -> 0.56578045
B30: Total Debt | D30: =F11 -> 1648 | E30: =D30/$D$32 -> 0.0026300897 | F30: =I18 -> 0.0052336836 | H30: Target Debt / Equity | L30: =F34 -> 0.0052612192
